[13/02/2014 11:40:43 PM] - ERROR - status.py - MainThread - write - Traceback (most recent call last):

[13/02/2014 11:40:43 PM] - ERROR - status.py - MainThread - write -   File "/usr/bin/i3situation", line 9, in <module>

[13/02/2014 11:40:43 PM] - ERROR - status.py - MainThread - write -     
[13/02/2014 11:40:43 PM] - ERROR - status.py - MainThread - write - load_entry_point('i3situation==1.0.2', 'console_scripts', 'i3situation')()
[13/02/2014 11:40:43 PM] - ERROR - status.py - MainThread - write -   File "/usr/lib/python3.3/site-packages/i3situation-1.0.2-py3.3.egg/i3situation/main.py", line 9, in main

[13/02/2014 11:40:43 PM] - ERROR - status.py - MainThread - write -     
[13/02/2014 11:40:43 PM] - ERROR - status.py - MainThread - write - s.run()
[13/02/2014 11:40:43 PM] - ERROR - status.py - MainThread - write -   File "/usr/lib/python3.3/site-packages/i3situation-1.0.2-py3.3.egg/i3situation/core/status.py", line 126, in run

[13/02/2014 11:40:43 PM] - ERROR - status.py - MainThread - write -     
[13/02/2014 11:40:43 PM] - ERROR - status.py - MainThread - write - time.sleep(self.config.general['interval'])
[13/02/2014 11:40:43 PM] - ERROR - status.py - MainThread - write - KeyboardInterrupt
[13/02/2014 11:40:43 PM] - ERROR - status.py - MainThread - write - 
[13/02/2014 11:40:44 PM] - ERROR - status.py - MainThread - write - Exception 
[13/02/2014 11:40:44 PM] - ERROR - status.py - MainThread - write - KeyboardInterrupt
[13/02/2014 11:40:44 PM] - ERROR - status.py - MainThread - write - : 
[13/02/2014 11:40:44 PM] - ERROR - status.py - MainThread - write - KeyboardInterrupt()
[13/02/2014 11:40:44 PM] - ERROR - status.py - MainThread - write -  in 
[13/02/2014 11:40:44 PM] - ERROR - status.py - MainThread - write - <module 'threading' from '/usr/lib/python3.3/threading.py'>
[13/02/2014 11:40:44 PM] - ERROR - status.py - MainThread - write -  ignored

[13/02/2014 11:41:37 PM] - ERROR - status.py - MainThread - write - Traceback (most recent call last):

[13/02/2014 11:41:37 PM] - ERROR - status.py - MainThread - write -   File "/usr/bin/i3situation", line 9, in <module>

[13/02/2014 11:41:37 PM] - ERROR - status.py - MainThread - write -     
[13/02/2014 11:41:37 PM] - ERROR - status.py - MainThread - write - load_entry_point('i3situation==1.0.2', 'console_scripts', 'i3situation')()
[13/02/2014 11:41:37 PM] - ERROR - status.py - MainThread - write -   File "/usr/lib/python3.3/site-packages/i3situation-1.0.2-py3.3.egg/i3situation/main.py", line 9, in main

[13/02/2014 11:41:37 PM] - ERROR - status.py - MainThread - write -     
[13/02/2014 11:41:37 PM] - ERROR - status.py - MainThread - write - s.run()
[13/02/2014 11:41:37 PM] - ERROR - status.py - MainThread - write -   File "/usr/lib/python3.3/site-packages/i3situation-1.0.2-py3.3.egg/i3situation/core/status.py", line 126, in run

[13/02/2014 11:41:37 PM] - ERROR - status.py - MainThread - write -     
[13/02/2014 11:41:37 PM] - ERROR - status.py - MainThread - write - time.sleep(self.config.general['interval'])
[13/02/2014 11:41:37 PM] - ERROR - status.py - MainThread - write - KeyboardInterrupt
[13/02/2014 11:41:37 PM] - ERROR - status.py - MainThread - write - 
[13/02/2014 11:41:37 PM] - ERROR - status.py - Thread-1 - write - Exception in thread Thread-1:
Traceback (most recent call last):
  File "/usr/lib/python3.3/json/decoder.py", line 368, in raw_decode
    obj, end = self.scan_once(s, idx)
StopIteration

During handling of the above exception, another exception occurred:

Traceback (most recent call last):
  File "/usr/lib/python3.3/threading.py", line 901, in _bootstrap_inner
    self.run()
  File "/usr/lib/python3.3/threading.py", line 858, in run
    self._target(*self._args, **self._kwargs)
  File "/usr/lib/python3.3/site-packages/i3situation-1.0.2-py3.3.egg/i3situation/core/status.py", line 149, in handle_events
    name = json.loads(event.lstrip(','))['name']
  File "/usr/lib/python3.3/json/__init__.py", line 319, in loads
    return _default_decoder.decode(s)
  File "/usr/lib/python3.3/json/decoder.py", line 352, in decode
    obj, end = self.raw_decode(s, idx=_w(s, 0).end())
  File "/usr/lib/python3.3/json/decoder.py", line 370, in raw_decode
    raise ValueError("No JSON object could be decoded")
ValueError: No JSON object could be decoded


[13/02/2014 11:42:37 PM] - ERROR - status.py - MainThread - write - Traceback (most recent call last):

[13/02/2014 11:42:37 PM] - ERROR - status.py - MainThread - write -   File "/usr/bin/i3situation", line 9, in <module>

[13/02/2014 11:42:37 PM] - ERROR - status.py - MainThread - write -     
[13/02/2014 11:42:37 PM] - ERROR - status.py - MainThread - write - load_entry_point('i3situation==1.0.2', 'console_scripts', 'i3situation')()
[13/02/2014 11:42:37 PM] - ERROR - status.py - MainThread - write -   File "/usr/lib/python3.3/site-packages/i3situation-1.0.2-py3.3.egg/i3situation/main.py", line 9, in main

[13/02/2014 11:42:37 PM] - ERROR - status.py - MainThread - write -     
[13/02/2014 11:42:37 PM] - ERROR - status.py - MainThread - write - s.run()
[13/02/2014 11:42:37 PM] - ERROR - status.py - MainThread - write -   File "/usr/lib/python3.3/site-packages/i3situation-1.0.2-py3.3.egg/i3situation/core/status.py", line 126, in run

[13/02/2014 11:42:37 PM] - ERROR - status.py - MainThread - write -     
[13/02/2014 11:42:37 PM] - ERROR - status.py - MainThread - write - time.sleep(self.config.general['interval'])
[13/02/2014 11:42:37 PM] - ERROR - status.py - MainThread - write - KeyboardInterrupt
[13/02/2014 11:42:37 PM] - ERROR - status.py - MainThread - write - 
[13/02/2014 11:42:39 PM] - ERROR - status.py - MainThread - write - Exception 
[13/02/2014 11:42:39 PM] - ERROR - status.py - MainThread - write - KeyboardInterrupt
[13/02/2014 11:42:39 PM] - ERROR - status.py - MainThread - write - : 
[13/02/2014 11:42:39 PM] - ERROR - status.py - MainThread - write - KeyboardInterrupt()
[13/02/2014 11:42:39 PM] - ERROR - status.py - MainThread - write -  in 
[13/02/2014 11:42:39 PM] - ERROR - status.py - MainThread - write - <module 'threading' from '/usr/lib/python3.3/threading.py'>
[13/02/2014 11:42:39 PM] - ERROR - status.py - MainThread - write -  ignored

[13/02/2014 11:43:08 PM] - ERROR - status.py - MainThread - write - Traceback (most recent call last):

[13/02/2014 11:43:08 PM] - ERROR - status.py - MainThread - write -   File "/usr/bin/i3situation", line 9, in <module>

[13/02/2014 11:43:08 PM] - ERROR - status.py - MainThread - write -     
[13/02/2014 11:43:08 PM] - ERROR - status.py - MainThread - write - load_entry_point('i3situation==1.0.2', 'console_scripts', 'i3situation')()
[13/02/2014 11:43:08 PM] - ERROR - status.py - MainThread - write -   File "/usr/lib/python3.3/site-packages/i3situation-1.0.2-py3.3.egg/i3situation/main.py", line 9, in main

[13/02/2014 11:43:08 PM] - ERROR - status.py - MainThread - write -     
[13/02/2014 11:43:08 PM] - ERROR - status.py - MainThread - write - s.run()
[13/02/2014 11:43:08 PM] - ERROR - status.py - MainThread - write -   File "/usr/lib/python3.3/site-packages/i3situation-1.0.2-py3.3.egg/i3situation/core/status.py", line 126, in run

[13/02/2014 11:43:08 PM] - ERROR - status.py - MainThread - write -     
[13/02/2014 11:43:08 PM] - ERROR - status.py - MainThread - write - time.sleep(self.config.general['interval'])
[13/02/2014 11:43:08 PM] - ERROR - status.py - MainThread - write - KeyboardInterrupt
[13/02/2014 11:43:08 PM] - ERROR - status.py - MainThread - write - 
[13/02/2014 11:43:09 PM] - ERROR - status.py - MainThread - write - Exception 
[13/02/2014 11:43:09 PM] - ERROR - status.py - MainThread - write - KeyboardInterrupt
[13/02/2014 11:43:09 PM] - ERROR - status.py - MainThread - write - : 
[13/02/2014 11:43:09 PM] - ERROR - status.py - MainThread - write - KeyboardInterrupt()
[13/02/2014 11:43:09 PM] - ERROR - status.py - MainThread - write -  in 
[13/02/2014 11:43:09 PM] - ERROR - status.py - MainThread - write - <module 'threading' from '/usr/lib/python3.3/threading.py'>
[13/02/2014 11:43:09 PM] - ERROR - status.py - MainThread - write -  ignored

[13/02/2014 11:43:13 PM] - ERROR - status.py - MainThread - write - Traceback (most recent call last):

[13/02/2014 11:43:13 PM] - ERROR - status.py - MainThread - write -   File "/usr/bin/i3situation", line 9, in <module>

[13/02/2014 11:43:13 PM] - ERROR - status.py - MainThread - write -     
[13/02/2014 11:43:13 PM] - ERROR - status.py - MainThread - write - load_entry_point('i3situation==1.0.2', 'console_scripts', 'i3situation')()
[13/02/2014 11:43:13 PM] - ERROR - status.py - MainThread - write -   File "/usr/lib/python3.3/site-packages/i3situation-1.0.2-py3.3.egg/i3situation/main.py", line 9, in main

[13/02/2014 11:43:13 PM] - ERROR - status.py - MainThread - write -     
[13/02/2014 11:43:13 PM] - ERROR - status.py - MainThread - write - s.run()
[13/02/2014 11:43:13 PM] - ERROR - status.py - MainThread - write -   File "/usr/lib/python3.3/site-packages/i3situation-1.0.2-py3.3.egg/i3situation/core/status.py", line 126, in run

[13/02/2014 11:43:13 PM] - ERROR - status.py - MainThread - write -     
[13/02/2014 11:43:13 PM] - ERROR - status.py - MainThread - write - time.sleep(self.config.general['interval'])
[13/02/2014 11:43:13 PM] - ERROR - status.py - MainThread - write - KeyboardInterrupt
[13/02/2014 11:43:13 PM] - ERROR - status.py - MainThread - write - 
[13/02/2014 11:43:13 PM] - ERROR - status.py - MainThread - write - Exception 
[13/02/2014 11:43:13 PM] - ERROR - status.py - MainThread - write - KeyboardInterrupt
[13/02/2014 11:43:13 PM] - ERROR - status.py - MainThread - write - : 
[13/02/2014 11:43:13 PM] - ERROR - status.py - MainThread - write - KeyboardInterrupt()
[13/02/2014 11:43:13 PM] - ERROR - status.py - MainThread - write -  in 
[13/02/2014 11:43:13 PM] - ERROR - status.py - MainThread - write - <module 'threading' from '/usr/lib/python3.3/threading.py'>
[13/02/2014 11:43:13 PM] - ERROR - status.py - MainThread - write -  ignored

[13/02/2014 11:44:50 PM] - ERROR - status.py - MainThread - write - Traceback (most recent call last):

[13/02/2014 11:44:50 PM] - ERROR - status.py - MainThread - write -   File "/usr/bin/i3situation", line 9, in <module>

[13/02/2014 11:44:50 PM] - ERROR - status.py - MainThread - write -     
[13/02/2014 11:44:50 PM] - ERROR - status.py - MainThread - write - load_entry_point('i3situation==1.0.2', 'console_scripts', 'i3situation')()
[13/02/2014 11:44:50 PM] - ERROR - status.py - MainThread - write -   File "/usr/lib/python3.3/site-packages/i3situation-1.0.2-py3.3.egg/i3situation/main.py", line 9, in main

[13/02/2014 11:44:50 PM] - ERROR - status.py - MainThread - write -     
[13/02/2014 11:44:50 PM] - ERROR - status.py - MainThread - write - s.run()
[13/02/2014 11:44:50 PM] - ERROR - status.py - MainThread - write -   File "/usr/lib/python3.3/site-packages/i3situation-1.0.2-py3.3.egg/i3situation/core/status.py", line 126, in run

[13/02/2014 11:44:50 PM] - ERROR - status.py - MainThread - write -     
[13/02/2014 11:44:50 PM] - ERROR - status.py - MainThread - write - time.sleep(self.config.general['interval'])
[13/02/2014 11:44:50 PM] - ERROR - status.py - MainThread - write - KeyboardInterrupt
[13/02/2014 11:44:50 PM] - ERROR - status.py - MainThread - write - 
[13/02/2014 11:44:51 PM] - ERROR - status.py - MainThread - write - Exception 
[13/02/2014 11:44:51 PM] - ERROR - status.py - MainThread - write - KeyboardInterrupt
[13/02/2014 11:44:51 PM] - ERROR - status.py - MainThread - write - : 
[13/02/2014 11:44:51 PM] - ERROR - status.py - MainThread - write - KeyboardInterrupt()
[13/02/2014 11:44:51 PM] - ERROR - status.py - MainThread - write -  in 
[13/02/2014 11:44:51 PM] - ERROR - status.py - MainThread - write - <module 'threading' from '/usr/lib/python3.3/threading.py'>
[13/02/2014 11:44:51 PM] - ERROR - status.py - MainThread - write -  ignored

[13/02/2014 11:45:22 PM] - CRITICAL - plugin_manager.py - MainThread - load_objects - Missing plugin network was not found in /home/andrew/.config/i3situation/plugins
[13/02/2014 11:45:22 PM] - ERROR - status.py - MainThread - write - Traceback (most recent call last):

[13/02/2014 11:45:22 PM] - ERROR - status.py - MainThread - write -   File "/usr/bin/i3situation", line 9, in <module>

[13/02/2014 11:45:22 PM] - ERROR - status.py - MainThread - write -     
[13/02/2014 11:45:22 PM] - ERROR - status.py - MainThread - write - load_entry_point('i3situation==1.0.2', 'console_scripts', 'i3situation')()
[13/02/2014 11:45:22 PM] - ERROR - status.py - MainThread - write -   File "/usr/lib/python3.3/site-packages/i3situation-1.0.2-py3.3.egg/i3situation/main.py", line 9, in main

[13/02/2014 11:45:22 PM] - ERROR - status.py - MainThread - write -     
[13/02/2014 11:45:22 PM] - ERROR - status.py - MainThread - write - s.run()
[13/02/2014 11:45:22 PM] - ERROR - status.py - MainThread - write -   File "/usr/lib/python3.3/site-packages/i3situation-1.0.2-py3.3.egg/i3situation/core/status.py", line 123, in run

[13/02/2014 11:45:22 PM] - ERROR - status.py - MainThread - write -     
[13/02/2014 11:45:22 PM] - ERROR - status.py - MainThread - write - self.reload()
[13/02/2014 11:45:22 PM] - ERROR - status.py - MainThread - write -   File "/usr/lib/python3.3/site-packages/i3situation-1.0.2-py3.3.egg/i3situation/core/status.py", line 96, in reload

[13/02/2014 11:45:22 PM] - ERROR - status.py - MainThread - write -     
[13/02/2014 11:45:22 PM] - ERROR - status.py - MainThread - write - self._plugin_path, self.config.plugin)
[13/02/2014 11:45:22 PM] - ERROR - status.py - MainThread - write -   File "/usr/lib/python3.3/site-packages/i3situation-1.0.2-py3.3.egg/i3situation/core/plugin_manager.py", line 123, in __init__

[13/02/2014 11:45:22 PM] - ERROR - status.py - MainThread - write -     
[13/02/2014 11:45:22 PM] - ERROR - status.py - MainThread - write - self.objects = self.load_objects()
[13/02/2014 11:45:22 PM] - ERROR - status.py - MainThread - write -   File "/usr/lib/python3.3/site-packages/i3situation-1.0.2-py3.3.egg/i3situation/core/plugin_manager.py", line 179, in load_objects

[13/02/2014 11:45:22 PM] - ERROR - status.py - MainThread - write -     
[13/02/2014 11:45:22 PM] - ERROR - status.py - MainThread - write - settings['plugin'], self.dir_path))
[13/02/2014 11:45:22 PM] - ERROR - status.py - MainThread - write - i3situation.core.plugin_manager
[13/02/2014 11:45:22 PM] - ERROR - status.py - MainThread - write - .
[13/02/2014 11:45:22 PM] - ERROR - status.py - MainThread - write - MissingPlugin
[13/02/2014 11:45:22 PM] - ERROR - status.py - MainThread - write - : 
[13/02/2014 11:45:22 PM] - ERROR - status.py - MainThread - write - The plugin network was not found in /home/andrew/.config/i3situation/plugins
[13/02/2014 11:47:03 PM] - ERROR - status.py - Thread-4 - write - Exception in thread Thread-4:
Traceback (most recent call last):
  File "/usr/lib/python3.3/threading.py", line 901, in _bootstrap_inner
    self.run()
  File "/usr/lib/python3.3/site-packages/i3situation-1.0.2-py3.3.egg/i3situation/core/plugin_manager.py", line 52, in run
    ret = self.func()
  File "/home/andrew/.config/i3situation/plugins/network.py", line 21, in main
    iface = netifaces.ifaddresses(ifaceName).get(netifaces.AF_INET)
ValueError: You must specify a valid interface name.


[13/02/2014 11:47:05 PM] - ERROR - status.py - MainThread - write - Traceback (most recent call last):

[13/02/2014 11:47:05 PM] - ERROR - status.py - MainThread - write -   File "/usr/bin/i3situation", line 9, in <module>

[13/02/2014 11:47:05 PM] - ERROR - status.py - MainThread - write -     
[13/02/2014 11:47:05 PM] - ERROR - status.py - MainThread - write - load_entry_point('i3situation==1.0.2', 'console_scripts', 'i3situation')()
[13/02/2014 11:47:05 PM] - ERROR - status.py - MainThread - write -   File "/usr/lib/python3.3/site-packages/i3situation-1.0.2-py3.3.egg/i3situation/main.py", line 9, in main

[13/02/2014 11:47:05 PM] - ERROR - status.py - MainThread - write -     
[13/02/2014 11:47:05 PM] - ERROR - status.py - MainThread - write - s.run()
[13/02/2014 11:47:05 PM] - ERROR - status.py - MainThread - write -   File "/usr/lib/python3.3/site-packages/i3situation-1.0.2-py3.3.egg/i3situation/core/status.py", line 126, in run

[13/02/2014 11:47:05 PM] - ERROR - status.py - MainThread - write -     
[13/02/2014 11:47:05 PM] - ERROR - status.py - MainThread - write - time.sleep(self.config.general['interval'])
[13/02/2014 11:47:05 PM] - ERROR - status.py - MainThread - write - KeyboardInterrupt
[13/02/2014 11:47:05 PM] - ERROR - status.py - MainThread - write - 
[13/02/2014 11:47:06 PM] - ERROR - status.py - Thread-4 - write - Exception in thread Thread-4:
Traceback (most recent call last):
  File "/usr/lib/python3.3/threading.py", line 901, in _bootstrap_inner
    self.run()
  File "/usr/lib/python3.3/site-packages/i3situation-1.0.2-py3.3.egg/i3situation/core/plugin_manager.py", line 52, in run
    ret = self.func()
  File "/home/andrew/.config/i3situation/plugins/network.py", line 21, in main
    iface = netifaces.ifaddresses(ifaceName).get(netifaces.AF_INET)
ValueError: You must specify a valid interface name.


[13/02/2014 11:47:09 PM] - ERROR - status.py - MainThread - write - Exception 
[13/02/2014 11:47:09 PM] - ERROR - status.py - MainThread - write - KeyboardInterrupt
[13/02/2014 11:47:09 PM] - ERROR - status.py - MainThread - write - : 
[13/02/2014 11:47:09 PM] - ERROR - status.py - MainThread - write - KeyboardInterrupt()
[13/02/2014 11:47:09 PM] - ERROR - status.py - MainThread - write -  in 
[13/02/2014 11:47:09 PM] - ERROR - status.py - MainThread - write - <module 'threading' from '/usr/lib/python3.3/threading.py'>
[13/02/2014 11:47:09 PM] - ERROR - status.py - MainThread - write -  ignored

[13/02/2014 11:47:32 PM] - ERROR - status.py - Thread-10 - write - Exception in thread Thread-10:
Traceback (most recent call last):
  File "/usr/lib/python3.3/threading.py", line 901, in _bootstrap_inner
    self.run()
  File "/usr/lib/python3.3/site-packages/i3situation-1.0.2-py3.3.egg/i3situation/core/plugin_manager.py", line 52, in run
    ret = self.func()
  File "/home/andrew/.config/i3situation/plugins/network.py", line 21, in main
    iface = netifaces.ifaddresses(ifaceName).get(netifaces.AF_INET)
ValueError: You must specify a valid interface name.


[13/02/2014 11:47:33 PM] - ERROR - status.py - Thread-4 - write - Exception in thread Thread-4:
Traceback (most recent call last):
  File "/usr/lib/python3.3/threading.py", line 901, in _bootstrap_inner
    self.run()
  File "/usr/lib/python3.3/site-packages/i3situation-1.0.2-py3.3.egg/i3situation/core/plugin_manager.py", line 52, in run
    ret = self.func()
  File "/home/andrew/.config/i3situation/plugins/network.py", line 21, in main
    iface = netifaces.ifaddresses(ifaceName).get(netifaces.AF_INET)
ValueError: You must specify a valid interface name.


[13/02/2014 11:48:50 PM] - ERROR - status.py - Thread-10 - write - Exception in thread Thread-10:
Traceback (most recent call last):
  File "/usr/lib/python3.3/threading.py", line 901, in _bootstrap_inner
    self.run()
  File "/usr/lib/python3.3/site-packages/i3situation-1.0.2-py3.3.egg/i3situation/core/plugin_manager.py", line 52, in run
    ret = self.func()
  File "/home/andrew/.config/i3situation/plugins/network.py", line 21, in main
    iface = netifaces.ifaddresses(ifaceName).get(netifaces.AF_INET)
ValueError: You must specify a valid interface name.


[13/02/2014 11:48:51 PM] - ERROR - status.py - Thread-4 - write - Exception in thread Thread-4:
Traceback (most recent call last):
  File "/usr/lib/python3.3/threading.py", line 901, in _bootstrap_inner
    self.run()
  File "/usr/lib/python3.3/site-packages/i3situation-1.0.2-py3.3.egg/i3situation/core/plugin_manager.py", line 52, in run
    ret = self.func()
  File "/home/andrew/.config/i3situation/plugins/network.py", line 21, in main
    iface = netifaces.ifaddresses(ifaceName).get(netifaces.AF_INET)
ValueError: You must specify a valid interface name.


[13/02/2014 11:49:03 PM] - ERROR - status.py - Thread-10 - write - Exception in thread Thread-10:
Traceback (most recent call last):
  File "/usr/lib/python3.3/threading.py", line 901, in _bootstrap_inner
    self.run()
  File "/usr/lib/python3.3/site-packages/i3situation-1.0.2-py3.3.egg/i3situation/core/plugin_manager.py", line 52, in run
    ret = self.func()
  File "/home/andrew/.config/i3situation/plugins/network.py", line 21, in main
    iface = netifaces.ifaddresses(ifaceName).get(netifaces.AF_INET)
ValueError: You must specify a valid interface name.


[13/02/2014 11:49:23 PM] - ERROR - status.py - Thread-16 - write - Exception in thread Thread-16:
Traceback (most recent call last):
  File "/usr/lib/python3.3/threading.py", line 901, in _bootstrap_inner
    self.run()
  File "/usr/lib/python3.3/site-packages/i3situation-1.0.2-py3.3.egg/i3situation/core/plugin_manager.py", line 52, in run
    ret = self.func()
  File "/home/andrew/.config/i3situation/plugins/network.py", line 21, in main
    iface = netifaces.ifaddresses(ifaceName).get(netifaces.AF_INET)
ValueError: You must specify a valid interface name.


[14/02/2014 10:39:22 PM] - ERROR - status.py - Thread-4 - write - Exception in thread Thread-4:
Traceback (most recent call last):
  File "/usr/lib/python3.3/threading.py", line 901, in _bootstrap_inner
    self.run()
  File "/usr/lib/python3.3/site-packages/i3situation-1.0.2-py3.3.egg/i3situation/core/plugin_manager.py", line 52, in run
    ret = self.func()
  File "/home/andrew/.config/i3situation/plugins/network.py", line 21, in main
    iface = netifaces.ifaddresses(ifaceName).get(netifaces.AF_INET)
ValueError: You must specify a valid interface name.


[16/02/2014 06:07:02 PM] - ERROR - status.py - Thread-4 - write - Exception in thread Thread-4:
Traceback (most recent call last):
  File "/usr/lib/python3.3/threading.py", line 901, in _bootstrap_inner
    self.run()
  File "/usr/lib/python3.3/site-packages/i3situation-1.0.2-py3.3.egg/i3situation/core/plugin_manager.py", line 52, in run
    ret = self.func()
  File "/home/andrew/.config/i3situation/plugins/network.py", line 21, in main
    iface = netifaces.ifaddresses(ifaceName).get(netifaces.AF_INET)
ValueError: You must specify a valid interface name.


[02/03/2014 02:59:37 PM] - ERROR - status.py - Thread-4 - write - Exception in thread Thread-4:
Traceback (most recent call last):
  File "/usr/lib/python3.3/threading.py", line 901, in _bootstrap_inner
    self.run()
  File "/usr/lib/python3.3/site-packages/i3situation-1.0.2-py3.3.egg/i3situation/core/plugin_manager.py", line 52, in run
    ret = self.func()
  File "/home/andrew/.config/i3situation/plugins/network.py", line 21, in main
    iface = netifaces.ifaddresses(ifaceName).get(netifaces.AF_INET)
ValueError: You must specify a valid interface name.


[03/03/2014 12:08:52 AM] - ERROR - status.py - Thread-4 - write - Exception in thread Thread-4:
Traceback (most recent call last):
  File "/usr/lib/python3.3/threading.py", line 901, in _bootstrap_inner
    self.run()
  File "/usr/lib/python3.3/site-packages/i3situation-1.0.2-py3.3.egg/i3situation/core/plugin_manager.py", line 52, in run
    ret = self.func()
  File "/home/andrew/.config/i3situation/plugins/network.py", line 21, in main
    iface = netifaces.ifaddresses(ifaceName).get(netifaces.AF_INET)
ValueError: You must specify a valid interface name.


[03/03/2014 09:26:02 AM] - ERROR - status.py - Thread-4 - write - Exception in thread Thread-4:
Traceback (most recent call last):
  File "/usr/lib/python3.3/threading.py", line 901, in _bootstrap_inner
    self.run()
  File "/usr/lib/python3.3/site-packages/i3situation-1.0.2-py3.3.egg/i3situation/core/plugin_manager.py", line 52, in run
    ret = self.func()
  File "/home/andrew/.config/i3situation/plugins/network.py", line 21, in main
    iface = netifaces.ifaddresses(ifaceName).get(netifaces.AF_INET)
ValueError: You must specify a valid interface name.


[03/03/2014 05:57:52 PM] - ERROR - status.py - Thread-4 - write - Exception in thread Thread-4:
Traceback (most recent call last):
  File "/usr/lib/python3.3/threading.py", line 901, in _bootstrap_inner
    self.run()
  File "/usr/lib/python3.3/site-packages/i3situation-1.0.2-py3.3.egg/i3situation/core/plugin_manager.py", line 52, in run
    ret = self.func()
  File "/home/andrew/.config/i3situation/plugins/network.py", line 21, in main
    iface = netifaces.ifaddresses(ifaceName).get(netifaces.AF_INET)
ValueError: You must specify a valid interface name.


[04/03/2014 12:02:34 AM] - ERROR - status.py - Thread-4 - write - Exception in thread Thread-4:
Traceback (most recent call last):
  File "/usr/lib/python3.3/threading.py", line 901, in _bootstrap_inner
    self.run()
  File "/usr/lib/python3.3/site-packages/i3situation-1.0.2-py3.3.egg/i3situation/core/plugin_manager.py", line 52, in run
    ret = self.func()
  File "/home/andrew/.config/i3situation/plugins/network.py", line 21, in main
    iface = netifaces.ifaddresses(ifaceName).get(netifaces.AF_INET)
ValueError: You must specify a valid interface name.


[15/03/2014 04:16:50 PM] - ERROR - status.py - Thread-4 - write - Exception in thread Thread-4:
Traceback (most recent call last):
  File "/usr/lib/python3.3/threading.py", line 901, in _bootstrap_inner
    self.run()
  File "/usr/lib/python3.3/site-packages/i3situation-1.0.2-py3.3.egg/i3situation/core/plugin_manager.py", line 52, in run
    ret = self.func()
  File "/home/andrew/.config/i3situation/plugins/network.py", line 21, in main
    iface = netifaces.ifaddresses(ifaceName).get(netifaces.AF_INET)
ValueError: You must specify a valid interface name.


[18/03/2014 10:26:05 PM] - ERROR - status.py - Thread-4 - write - Exception in thread Thread-4:
Traceback (most recent call last):
  File "/usr/lib/python3.3/threading.py", line 901, in _bootstrap_inner
    self.run()
  File "/usr/lib/python3.3/site-packages/i3situation-1.0.2-py3.3.egg/i3situation/core/plugin_manager.py", line 52, in run
    ret = self.func()
  File "/home/andrew/.config/i3situation/plugins/network.py", line 21, in main
    iface = netifaces.ifaddresses(ifaceName).get(netifaces.AF_INET)
ValueError: You must specify a valid interface name.


[27/03/2014 04:03:08 PM] - ERROR - status.py - Thread-4 - write - Exception in thread Thread-4:
Traceback (most recent call last):
  File "/usr/lib/python3.3/threading.py", line 901, in _bootstrap_inner
    self.run()
  File "/usr/lib/python3.3/site-packages/i3situation-1.0.2-py3.3.egg/i3situation/core/plugin_manager.py", line 52, in run
    ret = self.func()
  File "/home/andrew/.config/i3situation/plugins/network.py", line 21, in main
    iface = netifaces.ifaddresses(ifaceName).get(netifaces.AF_INET)
ValueError: You must specify a valid interface name.


[27/03/2014 08:32:58 PM] - ERROR - status.py - Thread-4 - write - Exception in thread Thread-4:
Traceback (most recent call last):
  File "/usr/lib/python3.3/threading.py", line 901, in _bootstrap_inner
    self.run()
  File "/usr/lib/python3.3/site-packages/i3situation-1.0.2-py3.3.egg/i3situation/core/plugin_manager.py", line 52, in run
    ret = self.func()
  File "/home/andrew/.config/i3situation/plugins/network.py", line 21, in main
    iface = netifaces.ifaddresses(ifaceName).get(netifaces.AF_INET)
ValueError: You must specify a valid interface name.


[28/03/2014 08:15:37 PM] - ERROR - status.py - Thread-4 - write - Exception in thread Thread-4:
Traceback (most recent call last):
  File "/usr/lib/python3.3/threading.py", line 901, in _bootstrap_inner
    self.run()
  File "/usr/lib/python3.3/site-packages/i3situation-1.0.2-py3.3.egg/i3situation/core/plugin_manager.py", line 52, in run
    ret = self.func()
  File "/home/andrew/.config/i3situation/plugins/network.py", line 21, in main
    iface = netifaces.ifaddresses(ifaceName).get(netifaces.AF_INET)
ValueError: You must specify a valid interface name.


[29/03/2014 10:59:51 AM] - ERROR - status.py - Thread-4 - write - Exception in thread Thread-4:
Traceback (most recent call last):
  File "/usr/lib/python3.3/threading.py", line 901, in _bootstrap_inner
    self.run()
  File "/usr/lib/python3.3/site-packages/i3situation-1.0.2-py3.3.egg/i3situation/core/plugin_manager.py", line 52, in run
    ret = self.func()
  File "/home/andrew/.config/i3situation/plugins/network.py", line 21, in main
    iface = netifaces.ifaddresses(ifaceName).get(netifaces.AF_INET)
ValueError: You must specify a valid interface name.


[02/04/2014 10:37:09 PM] - ERROR - status.py - Thread-4 - write - Exception in thread Thread-4:
Traceback (most recent call last):
  File "/usr/lib/python3.3/threading.py", line 901, in _bootstrap_inner
    self.run()
  File "/usr/lib/python3.3/site-packages/i3situation-1.0.2-py3.3.egg/i3situation/core/plugin_manager.py", line 52, in run
    ret = self.func()
  File "/home/andrew/.config/i3situation/plugins/network.py", line 21, in main
    iface = netifaces.ifaddresses(ifaceName).get(netifaces.AF_INET)
ValueError: You must specify a valid interface name.


[02/04/2014 11:44:26 PM] - ERROR - status.py - Thread-4 - write - Exception in thread Thread-4:
Traceback (most recent call last):
  File "/usr/lib/python3.3/threading.py", line 901, in _bootstrap_inner
    self.run()
  File "/usr/lib/python3.3/site-packages/i3situation-1.0.2-py3.3.egg/i3situation/core/plugin_manager.py", line 52, in run
    ret = self.func()
  File "/home/andrew/.config/i3situation/plugins/network.py", line 21, in main
    iface = netifaces.ifaddresses(ifaceName).get(netifaces.AF_INET)
ValueError: You must specify a valid interface name.


[03/04/2014 12:44:08 AM] - ERROR - status.py - Thread-4 - write - Exception in thread Thread-4:
Traceback (most recent call last):
  File "/usr/lib/python3.3/threading.py", line 901, in _bootstrap_inner
    self.run()
  File "/usr/lib/python3.3/site-packages/i3situation-1.0.2-py3.3.egg/i3situation/core/plugin_manager.py", line 52, in run
    ret = self.func()
  File "/home/andrew/.config/i3situation/plugins/network.py", line 21, in main
    iface = netifaces.ifaddresses(ifaceName).get(netifaces.AF_INET)
ValueError: You must specify a valid interface name.


[03/04/2014 12:45:37 AM] - CRITICAL - plugin_manager.py - MainThread - load_objects - Missing plugin network was not found in /home/andrew/.config/i3situation/plugins
[03/04/2014 12:45:37 AM] - ERROR - status.py - MainThread - write - Traceback (most recent call last):

[03/04/2014 12:45:37 AM] - ERROR - status.py - MainThread - write -   File "/usr/bin/i3situation", line 9, in <module>

[03/04/2014 12:45:37 AM] - ERROR - status.py - MainThread - write -     
[03/04/2014 12:45:37 AM] - ERROR - status.py - MainThread - write - load_entry_point('i3situation==1.0.3', 'console_scripts', 'i3situation')()
[03/04/2014 12:45:37 AM] - ERROR - status.py - MainThread - write -   File "/usr/lib/python3.3/site-packages/i3situation-1.0.3-py3.3.egg/i3situation/main.py", line 7, in main

[03/04/2014 12:45:37 AM] - ERROR - status.py - MainThread - write -     
[03/04/2014 12:45:37 AM] - ERROR - status.py - MainThread - write - s = status.Status()
[03/04/2014 12:45:37 AM] - ERROR - status.py - MainThread - write -   File "/usr/lib/python3.3/site-packages/i3situation-1.0.3-py3.3.egg/i3situation/core/status.py", line 60, in __init__

[03/04/2014 12:45:37 AM] - ERROR - status.py - MainThread - write -     
[03/04/2014 12:45:37 AM] - ERROR - status.py - MainThread - write - self._plugin_path, self.config.plugin)
[03/04/2014 12:45:37 AM] - ERROR - status.py - MainThread - write -   File "/usr/lib/python3.3/site-packages/i3situation-1.0.3-py3.3.egg/i3situation/core/plugin_manager.py", line 123, in __init__

[03/04/2014 12:45:37 AM] - ERROR - status.py - MainThread - write -     
[03/04/2014 12:45:37 AM] - ERROR - status.py - MainThread - write - self.objects = self.load_objects()
[03/04/2014 12:45:37 AM] - ERROR - status.py - MainThread - write -   File "/usr/lib/python3.3/site-packages/i3situation-1.0.3-py3.3.egg/i3situation/core/plugin_manager.py", line 179, in load_objects

[03/04/2014 12:45:37 AM] - ERROR - status.py - MainThread - write -     
[03/04/2014 12:45:37 AM] - ERROR - status.py - MainThread - write - settings['plugin'], self.dir_path))
[03/04/2014 12:45:37 AM] - ERROR - status.py - MainThread - write - i3situation.core.plugin_manager
[03/04/2014 12:45:37 AM] - ERROR - status.py - MainThread - write - .
[03/04/2014 12:45:37 AM] - ERROR - status.py - MainThread - write - MissingPlugin
[03/04/2014 12:45:37 AM] - ERROR - status.py - MainThread - write - : 
[03/04/2014 12:45:37 AM] - ERROR - status.py - MainThread - write - The plugin network was not found in /home/andrew/.config/i3situation/plugins
[03/04/2014 12:46:13 AM] - CRITICAL - plugin_manager.py - MainThread - load_objects - Missing plugin network was not found in /home/andrew/.config/i3situation/plugins
[03/04/2014 12:46:13 AM] - ERROR - status.py - MainThread - write - Traceback (most recent call last):

[03/04/2014 12:46:13 AM] - ERROR - status.py - MainThread - write -   File "/usr/bin/i3situation", line 9, in <module>

[03/04/2014 12:46:13 AM] - ERROR - status.py - MainThread - write -     
[03/04/2014 12:46:13 AM] - ERROR - status.py - MainThread - write - load_entry_point('i3situation==1.0.3', 'console_scripts', 'i3situation')()
[03/04/2014 12:46:13 AM] - ERROR - status.py - MainThread - write -   File "/usr/lib/python3.3/site-packages/i3situation-1.0.3-py3.3.egg/i3situation/main.py", line 7, in main

[03/04/2014 12:46:13 AM] - ERROR - status.py - MainThread - write -     
[03/04/2014 12:46:13 AM] - ERROR - status.py - MainThread - write - s = status.Status()
[03/04/2014 12:46:13 AM] - ERROR - status.py - MainThread - write -   File "/usr/lib/python3.3/site-packages/i3situation-1.0.3-py3.3.egg/i3situation/core/status.py", line 60, in __init__

[03/04/2014 12:46:13 AM] - ERROR - status.py - MainThread - write -     
[03/04/2014 12:46:13 AM] - ERROR - status.py - MainThread - write - self._plugin_path, self.config.plugin)
[03/04/2014 12:46:13 AM] - ERROR - status.py - MainThread - write -   File "/usr/lib/python3.3/site-packages/i3situation-1.0.3-py3.3.egg/i3situation/core/plugin_manager.py", line 123, in __init__

[03/04/2014 12:46:13 AM] - ERROR - status.py - MainThread - write -     
[03/04/2014 12:46:13 AM] - ERROR - status.py - MainThread - write - self.objects = self.load_objects()
[03/04/2014 12:46:13 AM] - ERROR - status.py - MainThread - write -   File "/usr/lib/python3.3/site-packages/i3situation-1.0.3-py3.3.egg/i3situation/core/plugin_manager.py", line 179, in load_objects

[03/04/2014 12:46:13 AM] - ERROR - status.py - MainThread - write -     
[03/04/2014 12:46:13 AM] - ERROR - status.py - MainThread - write - settings['plugin'], self.dir_path))
[03/04/2014 12:46:13 AM] - ERROR - status.py - MainThread - write - i3situation.core.plugin_manager
[03/04/2014 12:46:13 AM] - ERROR - status.py - MainThread - write - .
[03/04/2014 12:46:13 AM] - ERROR - status.py - MainThread - write - MissingPlugin
[03/04/2014 12:46:13 AM] - ERROR - status.py - MainThread - write - : 
[03/04/2014 12:46:13 AM] - ERROR - status.py - MainThread - write - The plugin network was not found in /home/andrew/.config/i3situation/plugins
[03/04/2014 12:46:45 AM] - CRITICAL - plugin_manager.py - MainThread - load_objects - Missing plugin network was not found in /home/andrew/.config/i3situation/plugins
[03/04/2014 12:46:45 AM] - ERROR - status.py - MainThread - write - Traceback (most recent call last):

[03/04/2014 12:46:45 AM] - ERROR - status.py - MainThread - write -   File "/usr/bin/i3situation", line 9, in <module>

[03/04/2014 12:46:45 AM] - ERROR - status.py - MainThread - write -     
[03/04/2014 12:46:45 AM] - ERROR - status.py - MainThread - write - load_entry_point('i3situation==1.0.3', 'console_scripts', 'i3situation')()
[03/04/2014 12:46:45 AM] - ERROR - status.py - MainThread - write -   File "/usr/lib/python3.3/site-packages/i3situation-1.0.3-py3.3.egg/i3situation/main.py", line 7, in main

[03/04/2014 12:46:45 AM] - ERROR - status.py - MainThread - write -     
[03/04/2014 12:46:45 AM] - ERROR - status.py - MainThread - write - s = status.Status()
[03/04/2014 12:46:45 AM] - ERROR - status.py - MainThread - write -   File "/usr/lib/python3.3/site-packages/i3situation-1.0.3-py3.3.egg/i3situation/core/status.py", line 60, in __init__

[03/04/2014 12:46:45 AM] - ERROR - status.py - MainThread - write -     
[03/04/2014 12:46:45 AM] - ERROR - status.py - MainThread - write - self._plugin_path, self.config.plugin)
[03/04/2014 12:46:45 AM] - ERROR - status.py - MainThread - write -   File "/usr/lib/python3.3/site-packages/i3situation-1.0.3-py3.3.egg/i3situation/core/plugin_manager.py", line 123, in __init__

[03/04/2014 12:46:45 AM] - ERROR - status.py - MainThread - write -     
[03/04/2014 12:46:45 AM] - ERROR - status.py - MainThread - write - self.objects = self.load_objects()
[03/04/2014 12:46:45 AM] - ERROR - status.py - MainThread - write -   File "/usr/lib/python3.3/site-packages/i3situation-1.0.3-py3.3.egg/i3situation/core/plugin_manager.py", line 179, in load_objects

[03/04/2014 12:46:45 AM] - ERROR - status.py - MainThread - write -     
[03/04/2014 12:46:45 AM] - ERROR - status.py - MainThread - write - settings['plugin'], self.dir_path))
[03/04/2014 12:46:45 AM] - ERROR - status.py - MainThread - write - i3situation.core.plugin_manager
[03/04/2014 12:46:45 AM] - ERROR - status.py - MainThread - write - .
[03/04/2014 12:46:45 AM] - ERROR - status.py - MainThread - write - MissingPlugin
[03/04/2014 12:46:45 AM] - ERROR - status.py - MainThread - write - : 
[03/04/2014 12:46:45 AM] - ERROR - status.py - MainThread - write - The plugin network was not found in /home/andrew/.config/i3situation/plugins
[03/04/2014 12:46:50 AM] - CRITICAL - plugin_manager.py - MainThread - load_objects - Missing plugin network was not found in /home/andrew/.config/i3situation/plugins
[03/04/2014 12:46:50 AM] - ERROR - status.py - MainThread - write - Traceback (most recent call last):

[03/04/2014 12:46:50 AM] - ERROR - status.py - MainThread - write -   File "/usr/bin/i3situation", line 9, in <module>

[03/04/2014 12:46:50 AM] - ERROR - status.py - MainThread - write -     
[03/04/2014 12:46:50 AM] - ERROR - status.py - MainThread - write - load_entry_point('i3situation==1.0.3', 'console_scripts', 'i3situation')()
[03/04/2014 12:46:50 AM] - ERROR - status.py - MainThread - write -   File "/usr/lib/python3.3/site-packages/i3situation-1.0.3-py3.3.egg/i3situation/main.py", line 7, in main

[03/04/2014 12:46:50 AM] - ERROR - status.py - MainThread - write -     
[03/04/2014 12:46:50 AM] - ERROR - status.py - MainThread - write - s = status.Status()
[03/04/2014 12:46:50 AM] - ERROR - status.py - MainThread - write -   File "/usr/lib/python3.3/site-packages/i3situation-1.0.3-py3.3.egg/i3situation/core/status.py", line 60, in __init__

[03/04/2014 12:46:50 AM] - ERROR - status.py - MainThread - write -     
[03/04/2014 12:46:50 AM] - ERROR - status.py - MainThread - write - self._plugin_path, self.config.plugin)
[03/04/2014 12:46:50 AM] - ERROR - status.py - MainThread - write -   File "/usr/lib/python3.3/site-packages/i3situation-1.0.3-py3.3.egg/i3situation/core/plugin_manager.py", line 123, in __init__

[03/04/2014 12:46:50 AM] - ERROR - status.py - MainThread - write -     
[03/04/2014 12:46:50 AM] - ERROR - status.py - MainThread - write - self.objects = self.load_objects()
[03/04/2014 12:46:50 AM] - ERROR - status.py - MainThread - write -   File "/usr/lib/python3.3/site-packages/i3situation-1.0.3-py3.3.egg/i3situation/core/plugin_manager.py", line 179, in load_objects

[03/04/2014 12:46:50 AM] - ERROR - status.py - MainThread - write -     
[03/04/2014 12:46:50 AM] - ERROR - status.py - MainThread - write - settings['plugin'], self.dir_path))
[03/04/2014 12:46:50 AM] - ERROR - status.py - MainThread - write - i3situation.core.plugin_manager
[03/04/2014 12:46:50 AM] - ERROR - status.py - MainThread - write - .
[03/04/2014 12:46:50 AM] - ERROR - status.py - MainThread - write - MissingPlugin
[03/04/2014 12:46:50 AM] - ERROR - status.py - MainThread - write - : 
[03/04/2014 12:46:50 AM] - ERROR - status.py - MainThread - write - The plugin network was not found in /home/andrew/.config/i3situation/plugins
[03/04/2014 12:46:57 AM] - CRITICAL - plugin_manager.py - MainThread - load_objects - Missing plugin network was not found in /home/andrew/.config/i3situation/plugins
[03/04/2014 12:46:57 AM] - ERROR - status.py - MainThread - write - Traceback (most recent call last):

[03/04/2014 12:46:57 AM] - ERROR - status.py - MainThread - write -   File "/usr/bin/i3situation", line 9, in <module>

[03/04/2014 12:46:57 AM] - ERROR - status.py - MainThread - write -     
[03/04/2014 12:46:57 AM] - ERROR - status.py - MainThread - write - load_entry_point('i3situation==1.0.3', 'console_scripts', 'i3situation')()
[03/04/2014 12:46:57 AM] - ERROR - status.py - MainThread - write -   File "/usr/lib/python3.3/site-packages/i3situation-1.0.3-py3.3.egg/i3situation/main.py", line 7, in main

[03/04/2014 12:46:57 AM] - ERROR - status.py - MainThread - write -     
[03/04/2014 12:46:57 AM] - ERROR - status.py - MainThread - write - s = status.Status()
[03/04/2014 12:46:57 AM] - ERROR - status.py - MainThread - write -   File "/usr/lib/python3.3/site-packages/i3situation-1.0.3-py3.3.egg/i3situation/core/status.py", line 60, in __init__

[03/04/2014 12:46:57 AM] - ERROR - status.py - MainThread - write -     
[03/04/2014 12:46:57 AM] - ERROR - status.py - MainThread - write - self._plugin_path, self.config.plugin)
[03/04/2014 12:46:57 AM] - ERROR - status.py - MainThread - write -   File "/usr/lib/python3.3/site-packages/i3situation-1.0.3-py3.3.egg/i3situation/core/plugin_manager.py", line 123, in __init__

[03/04/2014 12:46:57 AM] - ERROR - status.py - MainThread - write -     
[03/04/2014 12:46:57 AM] - ERROR - status.py - MainThread - write - self.objects = self.load_objects()
[03/04/2014 12:46:57 AM] - ERROR - status.py - MainThread - write -   File "/usr/lib/python3.3/site-packages/i3situation-1.0.3-py3.3.egg/i3situation/core/plugin_manager.py", line 179, in load_objects

[03/04/2014 12:46:57 AM] - ERROR - status.py - MainThread - write -     
[03/04/2014 12:46:57 AM] - ERROR - status.py - MainThread - write - settings['plugin'], self.dir_path))
[03/04/2014 12:46:57 AM] - ERROR - status.py - MainThread - write - i3situation.core.plugin_manager
[03/04/2014 12:46:57 AM] - ERROR - status.py - MainThread - write - .
[03/04/2014 12:46:57 AM] - ERROR - status.py - MainThread - write - MissingPlugin
[03/04/2014 12:46:57 AM] - ERROR - status.py - MainThread - write - : 
[03/04/2014 12:46:57 AM] - ERROR - status.py - MainThread - write - The plugin network was not found in /home/andrew/.config/i3situation/plugins
[03/04/2014 12:47:29 AM] - CRITICAL - plugin_manager.py - MainThread - load_objects - Missing plugin network was not found in /home/andrew/.config/i3situation/plugins
[03/04/2014 12:47:29 AM] - ERROR - status.py - MainThread - write - Traceback (most recent call last):

[03/04/2014 12:47:29 AM] - ERROR - status.py - MainThread - write -   File "/usr/bin/i3situation", line 9, in <module>

[03/04/2014 12:47:29 AM] - ERROR - status.py - MainThread - write -     
[03/04/2014 12:47:29 AM] - ERROR - status.py - MainThread - write - load_entry_point('i3situation==1.0.3', 'console_scripts', 'i3situation')()
[03/04/2014 12:47:29 AM] - ERROR - status.py - MainThread - write -   File "/usr/lib/python3.3/site-packages/i3situation-1.0.3-py3.3.egg/i3situation/main.py", line 7, in main

[03/04/2014 12:47:29 AM] - ERROR - status.py - MainThread - write -     
[03/04/2014 12:47:29 AM] - ERROR - status.py - MainThread - write - s = status.Status()
[03/04/2014 12:47:29 AM] - ERROR - status.py - MainThread - write -   File "/usr/lib/python3.3/site-packages/i3situation-1.0.3-py3.3.egg/i3situation/core/status.py", line 60, in __init__

[03/04/2014 12:47:29 AM] - ERROR - status.py - MainThread - write -     
[03/04/2014 12:47:29 AM] - ERROR - status.py - MainThread - write - self._plugin_path, self.config.plugin)
[03/04/2014 12:47:29 AM] - ERROR - status.py - MainThread - write -   File "/usr/lib/python3.3/site-packages/i3situation-1.0.3-py3.3.egg/i3situation/core/plugin_manager.py", line 123, in __init__

[03/04/2014 12:47:29 AM] - ERROR - status.py - MainThread - write -     
[03/04/2014 12:47:29 AM] - ERROR - status.py - MainThread - write - self.objects = self.load_objects()
[03/04/2014 12:47:29 AM] - ERROR - status.py - MainThread - write -   File "/usr/lib/python3.3/site-packages/i3situation-1.0.3-py3.3.egg/i3situation/core/plugin_manager.py", line 179, in load_objects

[03/04/2014 12:47:29 AM] - ERROR - status.py - MainThread - write -     
[03/04/2014 12:47:29 AM] - ERROR - status.py - MainThread - write - settings['plugin'], self.dir_path))
[03/04/2014 12:47:29 AM] - ERROR - status.py - MainThread - write - i3situation.core.plugin_manager
[03/04/2014 12:47:29 AM] - ERROR - status.py - MainThread - write - .
[03/04/2014 12:47:29 AM] - ERROR - status.py - MainThread - write - MissingPlugin
[03/04/2014 12:47:29 AM] - ERROR - status.py - MainThread - write - : 
[03/04/2014 12:47:29 AM] - ERROR - status.py - MainThread - write - The plugin network was not found in /home/andrew/.config/i3situation/plugins
[03/04/2014 12:48:48 AM] - CRITICAL - plugin_manager.py - MainThread - load_objects - Missing plugin network was not found in /home/andrew/.config/i3situation/plugins
[03/04/2014 12:48:48 AM] - ERROR - status.py - MainThread - write - Traceback (most recent call last):

[03/04/2014 12:48:48 AM] - ERROR - status.py - MainThread - write -   File "/usr/bin/i3situation", line 9, in <module>

[03/04/2014 12:48:48 AM] - ERROR - status.py - MainThread - write -     
[03/04/2014 12:48:48 AM] - ERROR - status.py - MainThread - write - load_entry_point('i3situation==1.0.3', 'console_scripts', 'i3situation')()
[03/04/2014 12:48:48 AM] - ERROR - status.py - MainThread - write -   File "/usr/lib/python3.3/site-packages/i3situation-1.0.3-py3.3.egg/i3situation/main.py", line 7, in main

[03/04/2014 12:48:48 AM] - ERROR - status.py - MainThread - write -     
[03/04/2014 12:48:48 AM] - ERROR - status.py - MainThread - write - s = status.Status()
[03/04/2014 12:48:48 AM] - ERROR - status.py - MainThread - write -   File "/usr/lib/python3.3/site-packages/i3situation-1.0.3-py3.3.egg/i3situation/core/status.py", line 60, in __init__

[03/04/2014 12:48:48 AM] - ERROR - status.py - MainThread - write -     
[03/04/2014 12:48:48 AM] - ERROR - status.py - MainThread - write - self._plugin_path, self.config.plugin)
[03/04/2014 12:48:48 AM] - ERROR - status.py - MainThread - write -   File "/usr/lib/python3.3/site-packages/i3situation-1.0.3-py3.3.egg/i3situation/core/plugin_manager.py", line 123, in __init__

[03/04/2014 12:48:48 AM] - ERROR - status.py - MainThread - write -     
[03/04/2014 12:48:48 AM] - ERROR - status.py - MainThread - write - self.objects = self.load_objects()
[03/04/2014 12:48:48 AM] - ERROR - status.py - MainThread - write -   File "/usr/lib/python3.3/site-packages/i3situation-1.0.3-py3.3.egg/i3situation/core/plugin_manager.py", line 179, in load_objects

[03/04/2014 12:48:48 AM] - ERROR - status.py - MainThread - write -     
[03/04/2014 12:48:48 AM] - ERROR - status.py - MainThread - write - settings['plugin'], self.dir_path))
[03/04/2014 12:48:48 AM] - ERROR - status.py - MainThread - write - i3situation.core.plugin_manager
[03/04/2014 12:48:48 AM] - ERROR - status.py - MainThread - write - .
[03/04/2014 12:48:48 AM] - ERROR - status.py - MainThread - write - MissingPlugin
[03/04/2014 12:48:48 AM] - ERROR - status.py - MainThread - write - : 
[03/04/2014 12:48:48 AM] - ERROR - status.py - MainThread - write - The plugin network was not found in /home/andrew/.config/i3situation/plugins
[03/04/2014 12:50:42 AM] - CRITICAL - plugin_manager.py - MainThread - load_objects - Missing plugin network was not found in /home/andrew/.config/i3situation/plugins
[03/04/2014 12:50:42 AM] - ERROR - status.py - MainThread - write - Traceback (most recent call last):

[03/04/2014 12:50:42 AM] - ERROR - status.py - MainThread - write -   File "/usr/bin/i3situation", line 9, in <module>

[03/04/2014 12:50:42 AM] - ERROR - status.py - MainThread - write -     
[03/04/2014 12:50:42 AM] - ERROR - status.py - MainThread - write - load_entry_point('i3situation==1.0.3', 'console_scripts', 'i3situation')()
[03/04/2014 12:50:42 AM] - ERROR - status.py - MainThread - write -   File "/usr/lib/python3.3/site-packages/i3situation-1.0.3-py3.3.egg/i3situation/main.py", line 7, in main

[03/04/2014 12:50:42 AM] - ERROR - status.py - MainThread - write -     
[03/04/2014 12:50:42 AM] - ERROR - status.py - MainThread - write - s = status.Status()
[03/04/2014 12:50:42 AM] - ERROR - status.py - MainThread - write -   File "/usr/lib/python3.3/site-packages/i3situation-1.0.3-py3.3.egg/i3situation/core/status.py", line 60, in __init__

[03/04/2014 12:50:42 AM] - ERROR - status.py - MainThread - write -     
[03/04/2014 12:50:42 AM] - ERROR - status.py - MainThread - write - self._plugin_path, self.config.plugin)
[03/04/2014 12:50:42 AM] - ERROR - status.py - MainThread - write -   File "/usr/lib/python3.3/site-packages/i3situation-1.0.3-py3.3.egg/i3situation/core/plugin_manager.py", line 123, in __init__

[03/04/2014 12:50:42 AM] - ERROR - status.py - MainThread - write -     
[03/04/2014 12:50:42 AM] - ERROR - status.py - MainThread - write - self.objects = self.load_objects()
[03/04/2014 12:50:42 AM] - ERROR - status.py - MainThread - write -   File "/usr/lib/python3.3/site-packages/i3situation-1.0.3-py3.3.egg/i3situation/core/plugin_manager.py", line 179, in load_objects

[03/04/2014 12:50:42 AM] - ERROR - status.py - MainThread - write -     
[03/04/2014 12:50:42 AM] - ERROR - status.py - MainThread - write - settings['plugin'], self.dir_path))
[03/04/2014 12:50:42 AM] - ERROR - status.py - MainThread - write - i3situation.core.plugin_manager
[03/04/2014 12:50:42 AM] - ERROR - status.py - MainThread - write - .
[03/04/2014 12:50:42 AM] - ERROR - status.py - MainThread - write - MissingPlugin
[03/04/2014 12:50:42 AM] - ERROR - status.py - MainThread - write - : 
[03/04/2014 12:50:42 AM] - ERROR - status.py - MainThread - write - The plugin network was not found in /home/andrew/.config/i3situation/plugins
[03/04/2014 12:51:01 AM] - CRITICAL - plugin_manager.py - MainThread - load_objects - Missing plugin network was not found in /home/andrew/.config/i3situation/plugins
[03/04/2014 12:51:01 AM] - ERROR - status.py - MainThread - write - Traceback (most recent call last):

[03/04/2014 12:51:01 AM] - ERROR - status.py - MainThread - write -   File "/usr/bin/i3situation", line 9, in <module>

[03/04/2014 12:51:01 AM] - ERROR - status.py - MainThread - write -     
[03/04/2014 12:51:01 AM] - ERROR - status.py - MainThread - write - load_entry_point('i3situation==1.0.3', 'console_scripts', 'i3situation')()
[03/04/2014 12:51:01 AM] - ERROR - status.py - MainThread - write -   File "/usr/lib/python3.3/site-packages/i3situation-1.0.3-py3.3.egg/i3situation/main.py", line 7, in main

[03/04/2014 12:51:01 AM] - ERROR - status.py - MainThread - write -     
[03/04/2014 12:51:01 AM] - ERROR - status.py - MainThread - write - s = status.Status()
[03/04/2014 12:51:01 AM] - ERROR - status.py - MainThread - write -   File "/usr/lib/python3.3/site-packages/i3situation-1.0.3-py3.3.egg/i3situation/core/status.py", line 60, in __init__

[03/04/2014 12:51:01 AM] - ERROR - status.py - MainThread - write -     
[03/04/2014 12:51:01 AM] - ERROR - status.py - MainThread - write - self._plugin_path, self.config.plugin)
[03/04/2014 12:51:01 AM] - ERROR - status.py - MainThread - write -   File "/usr/lib/python3.3/site-packages/i3situation-1.0.3-py3.3.egg/i3situation/core/plugin_manager.py", line 123, in __init__

[03/04/2014 12:51:01 AM] - ERROR - status.py - MainThread - write -     
[03/04/2014 12:51:01 AM] - ERROR - status.py - MainThread - write - self.objects = self.load_objects()
[03/04/2014 12:51:01 AM] - ERROR - status.py - MainThread - write -   File "/usr/lib/python3.3/site-packages/i3situation-1.0.3-py3.3.egg/i3situation/core/plugin_manager.py", line 179, in load_objects

[03/04/2014 12:51:01 AM] - ERROR - status.py - MainThread - write -     
[03/04/2014 12:51:01 AM] - ERROR - status.py - MainThread - write - settings['plugin'], self.dir_path))
[03/04/2014 12:51:01 AM] - ERROR - status.py - MainThread - write - i3situation.core.plugin_manager
[03/04/2014 12:51:01 AM] - ERROR - status.py - MainThread - write - .
[03/04/2014 12:51:01 AM] - ERROR - status.py - MainThread - write - MissingPlugin
[03/04/2014 12:51:01 AM] - ERROR - status.py - MainThread - write - : 
[03/04/2014 12:51:01 AM] - ERROR - status.py - MainThread - write - The plugin network was not found in /home/andrew/.config/i3situation/plugins
[03/04/2014 12:51:03 AM] - CRITICAL - plugin_manager.py - MainThread - load_objects - Missing plugin network was not found in /home/andrew/.config/i3situation/plugins
[03/04/2014 12:51:03 AM] - ERROR - status.py - MainThread - write - Traceback (most recent call last):

[03/04/2014 12:51:03 AM] - ERROR - status.py - MainThread - write -   File "/usr/bin/i3situation", line 9, in <module>

[03/04/2014 12:51:03 AM] - ERROR - status.py - MainThread - write -     
[03/04/2014 12:51:03 AM] - ERROR - status.py - MainThread - write - load_entry_point('i3situation==1.0.3', 'console_scripts', 'i3situation')()
[03/04/2014 12:51:03 AM] - ERROR - status.py - MainThread - write -   File "/usr/lib/python3.3/site-packages/i3situation-1.0.3-py3.3.egg/i3situation/main.py", line 7, in main

[03/04/2014 12:51:03 AM] - ERROR - status.py - MainThread - write -     
[03/04/2014 12:51:03 AM] - ERROR - status.py - MainThread - write - s = status.Status()
[03/04/2014 12:51:03 AM] - ERROR - status.py - MainThread - write -   File "/usr/lib/python3.3/site-packages/i3situation-1.0.3-py3.3.egg/i3situation/core/status.py", line 60, in __init__

[03/04/2014 12:51:03 AM] - ERROR - status.py - MainThread - write -     
[03/04/2014 12:51:03 AM] - ERROR - status.py - MainThread - write - self._plugin_path, self.config.plugin)
[03/04/2014 12:51:03 AM] - ERROR - status.py - MainThread - write -   File "/usr/lib/python3.3/site-packages/i3situation-1.0.3-py3.3.egg/i3situation/core/plugin_manager.py", line 123, in __init__

[03/04/2014 12:51:03 AM] - ERROR - status.py - MainThread - write -     
[03/04/2014 12:51:03 AM] - ERROR - status.py - MainThread - write - self.objects = self.load_objects()
[03/04/2014 12:51:03 AM] - ERROR - status.py - MainThread - write -   File "/usr/lib/python3.3/site-packages/i3situation-1.0.3-py3.3.egg/i3situation/core/plugin_manager.py", line 179, in load_objects

[03/04/2014 12:51:03 AM] - ERROR - status.py - MainThread - write -     
[03/04/2014 12:51:03 AM] - ERROR - status.py - MainThread - write - settings['plugin'], self.dir_path))
[03/04/2014 12:51:03 AM] - ERROR - status.py - MainThread - write - i3situation.core.plugin_manager
[03/04/2014 12:51:03 AM] - ERROR - status.py - MainThread - write - .
[03/04/2014 12:51:03 AM] - ERROR - status.py - MainThread - write - MissingPlugin
[03/04/2014 12:51:03 AM] - ERROR - status.py - MainThread - write - : 
[03/04/2014 12:51:03 AM] - ERROR - status.py - MainThread - write - The plugin network was not found in /home/andrew/.config/i3situation/plugins
[03/04/2014 12:51:22 AM] - CRITICAL - plugin_manager.py - MainThread - load_objects - Missing plugin network was not found in /home/andrew/.config/i3situation/plugins
[03/04/2014 12:51:22 AM] - ERROR - status.py - MainThread - write - Traceback (most recent call last):

[03/04/2014 12:51:22 AM] - ERROR - status.py - MainThread - write -   File "/usr/bin/i3situation", line 9, in <module>

[03/04/2014 12:51:22 AM] - ERROR - status.py - MainThread - write -     
[03/04/2014 12:51:22 AM] - ERROR - status.py - MainThread - write - load_entry_point('i3situation==1.0.3', 'console_scripts', 'i3situation')()
[03/04/2014 12:51:22 AM] - ERROR - status.py - MainThread - write -   File "/usr/lib/python3.3/site-packages/i3situation-1.0.3-py3.3.egg/i3situation/main.py", line 7, in main

[03/04/2014 12:51:22 AM] - ERROR - status.py - MainThread - write -     
[03/04/2014 12:51:22 AM] - ERROR - status.py - MainThread - write - s = status.Status()
[03/04/2014 12:51:22 AM] - ERROR - status.py - MainThread - write -   File "/usr/lib/python3.3/site-packages/i3situation-1.0.3-py3.3.egg/i3situation/core/status.py", line 60, in __init__

[03/04/2014 12:51:22 AM] - ERROR - status.py - MainThread - write -     
[03/04/2014 12:51:22 AM] - ERROR - status.py - MainThread - write - self._plugin_path, self.config.plugin)
[03/04/2014 12:51:22 AM] - ERROR - status.py - MainThread - write -   File "/usr/lib/python3.3/site-packages/i3situation-1.0.3-py3.3.egg/i3situation/core/plugin_manager.py", line 123, in __init__

[03/04/2014 12:51:22 AM] - ERROR - status.py - MainThread - write -     
[03/04/2014 12:51:22 AM] - ERROR - status.py - MainThread - write - self.objects = self.load_objects()
[03/04/2014 12:51:22 AM] - ERROR - status.py - MainThread - write -   File "/usr/lib/python3.3/site-packages/i3situation-1.0.3-py3.3.egg/i3situation/core/plugin_manager.py", line 179, in load_objects

[03/04/2014 12:51:22 AM] - ERROR - status.py - MainThread - write -     
[03/04/2014 12:51:22 AM] - ERROR - status.py - MainThread - write - settings['plugin'], self.dir_path))
[03/04/2014 12:51:22 AM] - ERROR - status.py - MainThread - write - i3situation.core.plugin_manager
[03/04/2014 12:51:22 AM] - ERROR - status.py - MainThread - write - .
[03/04/2014 12:51:22 AM] - ERROR - status.py - MainThread - write - MissingPlugin
[03/04/2014 12:51:22 AM] - ERROR - status.py - MainThread - write - : 
[03/04/2014 12:51:22 AM] - ERROR - status.py - MainThread - write - The plugin network was not found in /home/andrew/.config/i3situation/plugins
[03/04/2014 12:59:54 AM] - CRITICAL - plugin_manager.py - MainThread - load_objects - Missing plugin network was not found in /home/andrew/.config/i3situation/plugins
[03/04/2014 12:59:54 AM] - ERROR - status.py - MainThread - write - Traceback (most recent call last):

[03/04/2014 12:59:54 AM] - ERROR - status.py - MainThread - write -   File "/usr/bin/i3situation", line 9, in <module>

[03/04/2014 12:59:54 AM] - ERROR - status.py - MainThread - write -     
[03/04/2014 12:59:54 AM] - ERROR - status.py - MainThread - write - load_entry_point('i3situation==1.0.3', 'console_scripts', 'i3situation')()
[03/04/2014 12:59:54 AM] - ERROR - status.py - MainThread - write -   File "/usr/lib/python3.3/site-packages/i3situation-1.0.3-py3.3.egg/i3situation/main.py", line 7, in main

[03/04/2014 12:59:54 AM] - ERROR - status.py - MainThread - write -     
[03/04/2014 12:59:54 AM] - ERROR - status.py - MainThread - write - s = status.Status()
[03/04/2014 12:59:54 AM] - ERROR - status.py - MainThread - write -   File "/usr/lib/python3.3/site-packages/i3situation-1.0.3-py3.3.egg/i3situation/core/status.py", line 60, in __init__

[03/04/2014 12:59:54 AM] - ERROR - status.py - MainThread - write -     
[03/04/2014 12:59:54 AM] - ERROR - status.py - MainThread - write - self._plugin_path, self.config.plugin)
[03/04/2014 12:59:54 AM] - ERROR - status.py - MainThread - write -   File "/usr/lib/python3.3/site-packages/i3situation-1.0.3-py3.3.egg/i3situation/core/plugin_manager.py", line 123, in __init__

[03/04/2014 12:59:54 AM] - ERROR - status.py - MainThread - write -     
[03/04/2014 12:59:54 AM] - ERROR - status.py - MainThread - write - self.objects = self.load_objects()
[03/04/2014 12:59:54 AM] - ERROR - status.py - MainThread - write -   File "/usr/lib/python3.3/site-packages/i3situation-1.0.3-py3.3.egg/i3situation/core/plugin_manager.py", line 179, in load_objects

[03/04/2014 12:59:54 AM] - ERROR - status.py - MainThread - write -     
[03/04/2014 12:59:54 AM] - ERROR - status.py - MainThread - write - settings['plugin'], self.dir_path))
[03/04/2014 12:59:54 AM] - ERROR - status.py - MainThread - write - i3situation.core.plugin_manager
[03/04/2014 12:59:54 AM] - ERROR - status.py - MainThread - write - .
[03/04/2014 12:59:54 AM] - ERROR - status.py - MainThread - write - MissingPlugin
[03/04/2014 12:59:54 AM] - ERROR - status.py - MainThread - write - : 
[03/04/2014 12:59:54 AM] - ERROR - status.py - MainThread - write - The plugin network was not found in /home/andrew/.config/i3situation/plugins
[03/04/2014 12:59:59 AM] - CRITICAL - plugin_manager.py - MainThread - load_objects - Missing plugin network was not found in /home/andrew/.config/i3situation/plugins
[03/04/2014 12:59:59 AM] - ERROR - status.py - MainThread - write - Traceback (most recent call last):

[03/04/2014 12:59:59 AM] - ERROR - status.py - MainThread - write -   File "/usr/bin/i3situation", line 9, in <module>

[03/04/2014 12:59:59 AM] - ERROR - status.py - MainThread - write -     
[03/04/2014 12:59:59 AM] - ERROR - status.py - MainThread - write - load_entry_point('i3situation==1.0.3', 'console_scripts', 'i3situation')()
[03/04/2014 12:59:59 AM] - ERROR - status.py - MainThread - write -   File "/usr/lib/python3.3/site-packages/i3situation-1.0.3-py3.3.egg/i3situation/main.py", line 7, in main

[03/04/2014 12:59:59 AM] - ERROR - status.py - MainThread - write -     
[03/04/2014 12:59:59 AM] - ERROR - status.py - MainThread - write - s = status.Status()
[03/04/2014 12:59:59 AM] - ERROR - status.py - MainThread - write -   File "/usr/lib/python3.3/site-packages/i3situation-1.0.3-py3.3.egg/i3situation/core/status.py", line 60, in __init__

[03/04/2014 12:59:59 AM] - ERROR - status.py - MainThread - write -     
[03/04/2014 12:59:59 AM] - ERROR - status.py - MainThread - write - self._plugin_path, self.config.plugin)
[03/04/2014 12:59:59 AM] - ERROR - status.py - MainThread - write -   File "/usr/lib/python3.3/site-packages/i3situation-1.0.3-py3.3.egg/i3situation/core/plugin_manager.py", line 123, in __init__

[03/04/2014 12:59:59 AM] - ERROR - status.py - MainThread - write -     
[03/04/2014 12:59:59 AM] - ERROR - status.py - MainThread - write - self.objects = self.load_objects()
[03/04/2014 12:59:59 AM] - ERROR - status.py - MainThread - write -   File "/usr/lib/python3.3/site-packages/i3situation-1.0.3-py3.3.egg/i3situation/core/plugin_manager.py", line 179, in load_objects

[03/04/2014 12:59:59 AM] - ERROR - status.py - MainThread - write -     
[03/04/2014 12:59:59 AM] - ERROR - status.py - MainThread - write - settings['plugin'], self.dir_path))
[03/04/2014 12:59:59 AM] - ERROR - status.py - MainThread - write - i3situation.core.plugin_manager
[03/04/2014 12:59:59 AM] - ERROR - status.py - MainThread - write - .
[03/04/2014 12:59:59 AM] - ERROR - status.py - MainThread - write - MissingPlugin
[03/04/2014 12:59:59 AM] - ERROR - status.py - MainThread - write - : 
[03/04/2014 12:59:59 AM] - ERROR - status.py - MainThread - write - The plugin network was not found in /home/andrew/.config/i3situation/plugins
[03/04/2014 01:01:17 AM] - CRITICAL - plugin_manager.py - MainThread - load_objects - Missing plugin volume was not found in /home/andrew/.config/i3situation/plugins
[03/04/2014 01:01:17 AM] - ERROR - status.py - MainThread - write - Traceback (most recent call last):

[03/04/2014 01:01:17 AM] - ERROR - status.py - MainThread - write -   File "/usr/bin/i3situation", line 9, in <module>

[03/04/2014 01:01:17 AM] - ERROR - status.py - MainThread - write -     
[03/04/2014 01:01:17 AM] - ERROR - status.py - MainThread - write - load_entry_point('i3situation==1.0.3', 'console_scripts', 'i3situation')()
[03/04/2014 01:01:17 AM] - ERROR - status.py - MainThread - write -   File "/usr/lib/python3.3/site-packages/i3situation-1.0.3-py3.3.egg/i3situation/main.py", line 7, in main

[03/04/2014 01:01:17 AM] - ERROR - status.py - MainThread - write -     
[03/04/2014 01:01:17 AM] - ERROR - status.py - MainThread - write - s = status.Status()
[03/04/2014 01:01:17 AM] - ERROR - status.py - MainThread - write -   File "/usr/lib/python3.3/site-packages/i3situation-1.0.3-py3.3.egg/i3situation/core/status.py", line 60, in __init__

[03/04/2014 01:01:17 AM] - ERROR - status.py - MainThread - write -     
[03/04/2014 01:01:17 AM] - ERROR - status.py - MainThread - write - self._plugin_path, self.config.plugin)
[03/04/2014 01:01:17 AM] - ERROR - status.py - MainThread - write -   File "/usr/lib/python3.3/site-packages/i3situation-1.0.3-py3.3.egg/i3situation/core/plugin_manager.py", line 123, in __init__

[03/04/2014 01:01:17 AM] - ERROR - status.py - MainThread - write -     
[03/04/2014 01:01:17 AM] - ERROR - status.py - MainThread - write - self.objects = self.load_objects()
[03/04/2014 01:01:17 AM] - ERROR - status.py - MainThread - write -   File "/usr/lib/python3.3/site-packages/i3situation-1.0.3-py3.3.egg/i3situation/core/plugin_manager.py", line 179, in load_objects

[03/04/2014 01:01:17 AM] - ERROR - status.py - MainThread - write -     
[03/04/2014 01:01:17 AM] - ERROR - status.py - MainThread - write - settings['plugin'], self.dir_path))
[03/04/2014 01:01:17 AM] - ERROR - status.py - MainThread - write - i3situation.core.plugin_manager
[03/04/2014 01:01:17 AM] - ERROR - status.py - MainThread - write - .
[03/04/2014 01:01:17 AM] - ERROR - status.py - MainThread - write - MissingPlugin
[03/04/2014 01:01:17 AM] - ERROR - status.py - MainThread - write - : 
[03/04/2014 01:01:17 AM] - ERROR - status.py - MainThread - write - The plugin volume was not found in /home/andrew/.config/i3situation/plugins
[03/04/2014 01:01:59 AM] - ERROR - status.py - Thread-4 - write - Exception in thread Thread-4:
Traceback (most recent call last):
  File "/usr/lib/python3.3/threading.py", line 901, in _bootstrap_inner
    self.run()
  File "/usr/lib/python3.3/site-packages/i3situation-1.0.3-py3.3.egg/i3situation/core/plugin_manager.py", line 52, in run
    ret = self.func()
  File "/home/andrew/.config/i3situation/plugins/network.py", line 16, in main
    iface = netifaces.ifaddresses(ifaceName).get(netifaces.AF_INET)
ValueError: You must specify a valid interface name.


[03/04/2014 01:01:59 AM] - ERROR - status.py - Thread-6 - write - Exception in thread Thread-6:
Traceback (most recent call last):
  File "/usr/lib/python3.3/threading.py", line 901, in _bootstrap_inner
    self.run()
  File "/usr/lib/python3.3/site-packages/i3situation-1.0.3-py3.3.egg/i3situation/core/plugin_manager.py", line 52, in run
    ret = self.func()
  File "/usr/lib/python3.3/site-packages/i3situation-1.0.3-py3.3.egg/i3situation/plugins/battery.py", line 28, in main
    energy_now = int(self.get_battery_state('energy_now'))
  File "/usr/lib/python3.3/site-packages/i3situation-1.0.3-py3.3.egg/i3situation/plugins/battery.py", line 54, in get_battery_state
    with open(os.path.join(self.options['battery_path'], prop), 'r') as f:
FileNotFoundError: [Errno 2] No such file or directory: '/sys/class/power_supply/BAT0/energy_now'


[03/04/2014 12:02:00 AM] - ERROR - status.py - MainThread - write - Traceback (most recent call last):

[03/04/2014 12:02:00 AM] - ERROR - status.py - MainThread - write -   File "/usr/bin/i3situation", line 9, in <module>

[03/04/2014 12:02:00 AM] - ERROR - status.py - MainThread - write -     
[03/04/2014 12:02:00 AM] - ERROR - status.py - MainThread - write - load_entry_point('i3situation==1.0.3', 'console_scripts', 'i3situation')()
[03/04/2014 12:02:00 AM] - ERROR - status.py - MainThread - write -   File "/usr/lib/python3.3/site-packages/i3situation-1.0.3-py3.3.egg/i3situation/main.py", line 9, in main

[03/04/2014 12:02:00 AM] - ERROR - status.py - MainThread - write -     
[03/04/2014 12:02:00 AM] - ERROR - status.py - MainThread - write - s.run()
[03/04/2014 12:02:00 AM] - ERROR - status.py - MainThread - write -   File "/usr/lib/python3.3/site-packages/i3situation-1.0.3-py3.3.egg/i3situation/core/status.py", line 127, in run

[03/04/2014 12:02:00 AM] - ERROR - status.py - MainThread - write -     
[03/04/2014 12:02:00 AM] - ERROR - status.py - MainThread - write - time.sleep(self.config.general['interval'])
[03/04/2014 12:02:00 AM] - ERROR - status.py - MainThread - write - KeyboardInterrupt
[03/04/2014 12:02:00 AM] - ERROR - status.py - MainThread - write - 
[03/04/2014 01:02:07 AM] - ERROR - status.py - Thread-4 - write - Exception in thread Thread-4:
Traceback (most recent call last):
  File "/usr/lib/python3.3/threading.py", line 901, in _bootstrap_inner
    self.run()
  File "/usr/lib/python3.3/site-packages/i3situation-1.0.3-py3.3.egg/i3situation/core/plugin_manager.py", line 52, in run
    ret = self.func()
  File "/home/andrew/.config/i3situation/plugins/network.py", line 16, in main
    iface = netifaces.ifaddresses(ifaceName).get(netifaces.AF_INET)
ValueError: You must specify a valid interface name.


[03/04/2014 12:02:07 AM] - ERROR - status.py - Thread-6 - write - Exception in thread Thread-6:
Traceback (most recent call last):
  File "/usr/lib/python3.3/threading.py", line 901, in _bootstrap_inner
    self.run()
  File "/usr/lib/python3.3/site-packages/i3situation-1.0.3-py3.3.egg/i3situation/core/plugin_manager.py", line 52, in run
    ret = self.func()
  File "/usr/lib/python3.3/site-packages/i3situation-1.0.3-py3.3.egg/i3situation/plugins/battery.py", line 28, in main
    energy_now = int(self.get_battery_state('energy_now'))
  File "/usr/lib/python3.3/site-packages/i3situation-1.0.3-py3.3.egg/i3situation/plugins/battery.py", line 54, in get_battery_state
    with open(os.path.join(self.options['battery_path'], prop), 'r') as f:
FileNotFoundError: [Errno 2] No such file or directory: '/sys/class/power_supply/BAT0/energy_now'


[03/04/2014 12:02:09 AM] - ERROR - status.py - MainThread - write - Exception 
[03/04/2014 12:02:09 AM] - ERROR - status.py - MainThread - write - KeyboardInterrupt
[03/04/2014 12:02:09 AM] - ERROR - status.py - MainThread - write - : 
[03/04/2014 12:02:09 AM] - ERROR - status.py - MainThread - write - KeyboardInterrupt()
[03/04/2014 12:02:09 AM] - ERROR - status.py - MainThread - write -  in 
[03/04/2014 12:02:09 AM] - ERROR - status.py - MainThread - write - <module 'threading' from '/usr/lib/python3.3/threading.py'>
[03/04/2014 12:02:09 AM] - ERROR - status.py - MainThread - write -  ignored

[03/04/2014 12:07:38 AM] - ERROR - status.py - MainThread - write - Traceback (most recent call last):

[03/04/2014 12:07:38 AM] - ERROR - status.py - MainThread - write -   File "/usr/bin/i3situation", line 9, in <module>

[03/04/2014 12:07:38 AM] - ERROR - status.py - MainThread - write -     
[03/04/2014 12:07:38 AM] - ERROR - status.py - MainThread - write - load_entry_point('i3situation==1.0.3', 'console_scripts', 'i3situation')()
[03/04/2014 12:07:38 AM] - ERROR - status.py - MainThread - write -   File "/usr/lib/python3.3/site-packages/i3situation-1.0.3-py3.3.egg/i3situation/main.py", line 9, in main

[03/04/2014 12:07:38 AM] - ERROR - status.py - MainThread - write -     
[03/04/2014 12:07:38 AM] - ERROR - status.py - MainThread - write - s.run()
[03/04/2014 12:07:38 AM] - ERROR - status.py - MainThread - write -   File "/usr/lib/python3.3/site-packages/i3situation-1.0.3-py3.3.egg/i3situation/core/status.py", line 124, in run

[03/04/2014 12:07:38 AM] - ERROR - status.py - MainThread - write -     
[03/04/2014 12:07:38 AM] - ERROR - status.py - MainThread - write - self.reload()
[03/04/2014 12:07:38 AM] - ERROR - status.py - MainThread - write -   File "/usr/lib/python3.3/site-packages/i3situation-1.0.3-py3.3.egg/i3situation/core/status.py", line 94, in reload

[03/04/2014 12:07:38 AM] - ERROR - status.py - MainThread - write -     
[03/04/2014 12:07:38 AM] - ERROR - status.py - MainThread - write - self.config.plugin, self.config.general = self.config.reload()
[03/04/2014 12:07:38 AM] - ERROR - status.py - MainThread - write -   File "/usr/lib/python3.3/site-packages/i3situation-1.0.3-py3.3.egg/i3situation/core/config.py", line 65, in reload

[03/04/2014 12:07:38 AM] - ERROR - status.py - MainThread - write -     
[03/04/2014 12:07:38 AM] - ERROR - status.py - MainThread - write - plugin.append(dict(self._conf.items(section)))
[03/04/2014 12:07:38 AM] - ERROR - status.py - MainThread - write -   File "/usr/lib/python3.3/configparser.py", line 836, in items

[03/04/2014 12:07:38 AM] - ERROR - status.py - MainThread - write -     
[03/04/2014 12:07:38 AM] - ERROR - status.py - MainThread - write - return [(option, value_getter(option)) for option in d.keys()]
[03/04/2014 12:07:38 AM] - ERROR - status.py - MainThread - write -   File "/usr/lib/python3.3/configparser.py", line 836, in <listcomp>

[03/04/2014 12:07:38 AM] - ERROR - status.py - MainThread - write -     
[03/04/2014 12:07:38 AM] - ERROR - status.py - MainThread - write - return [(option, value_getter(option)) for option in d.keys()]
[03/04/2014 12:07:38 AM] - ERROR - status.py - MainThread - write -   File "/usr/lib/python3.3/configparser.py", line 833, in <lambda>

[03/04/2014 12:07:38 AM] - ERROR - status.py - MainThread - write -     
[03/04/2014 12:07:38 AM] - ERROR - status.py - MainThread - write - section, option, d[option], d)
[03/04/2014 12:07:38 AM] - ERROR - status.py - MainThread - write -   File "/usr/lib/python3.3/configparser.py", line 374, in before_get

[03/04/2014 12:07:38 AM] - ERROR - status.py - MainThread - write -     
[03/04/2014 12:07:38 AM] - ERROR - status.py - MainThread - write - self._interpolate_some(parser, option, L, value, section, defaults, 1)
[03/04/2014 12:07:38 AM] - ERROR - status.py - MainThread - write -   File "/usr/lib/python3.3/configparser.py", line 423, in _interpolate_some

[03/04/2014 12:07:38 AM] - ERROR - status.py - MainThread - write -     
[03/04/2014 12:07:38 AM] - ERROR - status.py - MainThread - write - "found: %r" % (rest,))
[03/04/2014 12:07:38 AM] - ERROR - status.py - MainThread - write - configparser
[03/04/2014 12:07:38 AM] - ERROR - status.py - MainThread - write - .
[03/04/2014 12:07:38 AM] - ERROR - status.py - MainThread - write - InterpolationSyntaxError
[03/04/2014 12:07:38 AM] - ERROR - status.py - MainThread - write - : 
[03/04/2014 12:07:38 AM] - ERROR - status.py - MainThread - write - '%' must be followed by '%' or '(', found: '%'
[03/04/2014 01:12:22 AM] - ERROR - status.py - MainThread - write - Traceback (most recent call last):

[03/04/2014 01:12:22 AM] - ERROR - status.py - MainThread - write -   File "/usr/bin/i3situation", line 9, in <module>

[03/04/2014 01:12:22 AM] - ERROR - status.py - MainThread - write -     
[03/04/2014 01:12:22 AM] - ERROR - status.py - MainThread - write - load_entry_point('i3situation==1.0.3', 'console_scripts', 'i3situation')()
[03/04/2014 01:12:22 AM] - ERROR - status.py - MainThread - write -   File "/usr/lib/python3.3/site-packages/i3situation-1.0.3-py3.3.egg/i3situation/main.py", line 7, in main

[03/04/2014 01:12:22 AM] - ERROR - status.py - MainThread - write -     
[03/04/2014 01:12:22 AM] - ERROR - status.py - MainThread - write - s = status.Status()
[03/04/2014 01:12:22 AM] - ERROR - status.py - MainThread - write -   File "/usr/lib/python3.3/site-packages/i3situation-1.0.3-py3.3.egg/i3situation/core/status.py", line 60, in __init__

[03/04/2014 01:12:22 AM] - ERROR - status.py - MainThread - write -     
[03/04/2014 01:12:22 AM] - ERROR - status.py - MainThread - write - self._plugin_path, self.config.plugin)
[03/04/2014 01:12:22 AM] - ERROR - status.py - MainThread - write -   File "/usr/lib/python3.3/site-packages/i3situation-1.0.3-py3.3.egg/i3situation/core/plugin_manager.py", line 123, in __init__

[03/04/2014 01:12:22 AM] - ERROR - status.py - MainThread - write -     
[03/04/2014 01:12:22 AM] - ERROR - status.py - MainThread - write - self.objects = self.load_objects()
[03/04/2014 01:12:22 AM] - ERROR - status.py - MainThread - write -   File "/usr/lib/python3.3/site-packages/i3situation-1.0.3-py3.3.egg/i3situation/core/plugin_manager.py", line 167, in load_objects

[03/04/2014 01:12:22 AM] - ERROR - status.py - MainThread - write -     
[03/04/2014 01:12:22 AM] - ERROR - status.py - MainThread - write - if settings['plugin'] in self.plugins:
[03/04/2014 01:12:22 AM] - ERROR - status.py - MainThread - write - KeyError
[03/04/2014 01:12:22 AM] - ERROR - status.py - MainThread - write - : 
[03/04/2014 01:12:22 AM] - ERROR - status.py - MainThread - write - 'plugin'
[03/04/2014 01:12:25 AM] - ERROR - status.py - MainThread - write - Traceback (most recent call last):

[03/04/2014 01:12:25 AM] - ERROR - status.py - MainThread - write -   File "/usr/bin/i3situation", line 9, in <module>

[03/04/2014 01:12:25 AM] - ERROR - status.py - MainThread - write -     
[03/04/2014 01:12:25 AM] - ERROR - status.py - MainThread - write - load_entry_point('i3situation==1.0.3', 'console_scripts', 'i3situation')()
[03/04/2014 01:12:25 AM] - ERROR - status.py - MainThread - write -   File "/usr/lib/python3.3/site-packages/i3situation-1.0.3-py3.3.egg/i3situation/main.py", line 7, in main

[03/04/2014 01:12:25 AM] - ERROR - status.py - MainThread - write -     
[03/04/2014 01:12:25 AM] - ERROR - status.py - MainThread - write - s = status.Status()
[03/04/2014 01:12:25 AM] - ERROR - status.py - MainThread - write -   File "/usr/lib/python3.3/site-packages/i3situation-1.0.3-py3.3.egg/i3situation/core/status.py", line 60, in __init__

[03/04/2014 01:12:25 AM] - ERROR - status.py - MainThread - write -     
[03/04/2014 01:12:25 AM] - ERROR - status.py - MainThread - write - self._plugin_path, self.config.plugin)
[03/04/2014 01:12:25 AM] - ERROR - status.py - MainThread - write -   File "/usr/lib/python3.3/site-packages/i3situation-1.0.3-py3.3.egg/i3situation/core/plugin_manager.py", line 123, in __init__

[03/04/2014 01:12:25 AM] - ERROR - status.py - MainThread - write -     
[03/04/2014 01:12:25 AM] - ERROR - status.py - MainThread - write - self.objects = self.load_objects()
[03/04/2014 01:12:25 AM] - ERROR - status.py - MainThread - write -   File "/usr/lib/python3.3/site-packages/i3situation-1.0.3-py3.3.egg/i3situation/core/plugin_manager.py", line 167, in load_objects

[03/04/2014 01:12:25 AM] - ERROR - status.py - MainThread - write -     
[03/04/2014 01:12:25 AM] - ERROR - status.py - MainThread - write - if settings['plugin'] in self.plugins:
[03/04/2014 01:12:25 AM] - ERROR - status.py - MainThread - write - KeyError
[03/04/2014 01:12:25 AM] - ERROR - status.py - MainThread - write - : 
[03/04/2014 01:12:25 AM] - ERROR - status.py - MainThread - write - 'plugin'
[03/04/2014 01:12:26 AM] - ERROR - status.py - MainThread - write - Traceback (most recent call last):

[03/04/2014 01:12:26 AM] - ERROR - status.py - MainThread - write -   File "/usr/bin/i3situation", line 9, in <module>

[03/04/2014 01:12:26 AM] - ERROR - status.py - MainThread - write -     
[03/04/2014 01:12:26 AM] - ERROR - status.py - MainThread - write - load_entry_point('i3situation==1.0.3', 'console_scripts', 'i3situation')()
[03/04/2014 01:12:26 AM] - ERROR - status.py - MainThread - write -   File "/usr/lib/python3.3/site-packages/i3situation-1.0.3-py3.3.egg/i3situation/main.py", line 7, in main

[03/04/2014 01:12:26 AM] - ERROR - status.py - MainThread - write -     
[03/04/2014 01:12:26 AM] - ERROR - status.py - MainThread - write - s = status.Status()
[03/04/2014 01:12:26 AM] - ERROR - status.py - MainThread - write -   File "/usr/lib/python3.3/site-packages/i3situation-1.0.3-py3.3.egg/i3situation/core/status.py", line 60, in __init__

[03/04/2014 01:12:26 AM] - ERROR - status.py - MainThread - write -     
[03/04/2014 01:12:26 AM] - ERROR - status.py - MainThread - write - self._plugin_path, self.config.plugin)
[03/04/2014 01:12:26 AM] - ERROR - status.py - MainThread - write -   File "/usr/lib/python3.3/site-packages/i3situation-1.0.3-py3.3.egg/i3situation/core/plugin_manager.py", line 123, in __init__

[03/04/2014 01:12:26 AM] - ERROR - status.py - MainThread - write -     
[03/04/2014 01:12:26 AM] - ERROR - status.py - MainThread - write - self.objects = self.load_objects()
[03/04/2014 01:12:26 AM] - ERROR - status.py - MainThread - write -   File "/usr/lib/python3.3/site-packages/i3situation-1.0.3-py3.3.egg/i3situation/core/plugin_manager.py", line 167, in load_objects

[03/04/2014 01:12:26 AM] - ERROR - status.py - MainThread - write -     
[03/04/2014 01:12:26 AM] - ERROR - status.py - MainThread - write - if settings['plugin'] in self.plugins:
[03/04/2014 01:12:26 AM] - ERROR - status.py - MainThread - write - KeyError
[03/04/2014 01:12:26 AM] - ERROR - status.py - MainThread - write - : 
[03/04/2014 01:12:26 AM] - ERROR - status.py - MainThread - write - 'plugin'
[03/04/2014 01:13:04 AM] - ERROR - status.py - MainThread - write - Traceback (most recent call last):

[03/04/2014 01:13:04 AM] - ERROR - status.py - MainThread - write -   File "/usr/bin/i3situation", line 9, in <module>

[03/04/2014 01:13:04 AM] - ERROR - status.py - MainThread - write -     
[03/04/2014 01:13:04 AM] - ERROR - status.py - MainThread - write - load_entry_point('i3situation==1.0.3', 'console_scripts', 'i3situation')()
[03/04/2014 01:13:04 AM] - ERROR - status.py - MainThread - write -   File "/usr/lib/python3.3/site-packages/i3situation-1.0.3-py3.3.egg/i3situation/main.py", line 7, in main

[03/04/2014 01:13:04 AM] - ERROR - status.py - MainThread - write -     
[03/04/2014 01:13:04 AM] - ERROR - status.py - MainThread - write - s = status.Status()
[03/04/2014 01:13:04 AM] - ERROR - status.py - MainThread - write -   File "/usr/lib/python3.3/site-packages/i3situation-1.0.3-py3.3.egg/i3situation/core/status.py", line 60, in __init__

[03/04/2014 01:13:04 AM] - ERROR - status.py - MainThread - write -     
[03/04/2014 01:13:04 AM] - ERROR - status.py - MainThread - write - self._plugin_path, self.config.plugin)
[03/04/2014 01:13:04 AM] - ERROR - status.py - MainThread - write -   File "/usr/lib/python3.3/site-packages/i3situation-1.0.3-py3.3.egg/i3situation/core/plugin_manager.py", line 123, in __init__

[03/04/2014 01:13:04 AM] - ERROR - status.py - MainThread - write -     
[03/04/2014 01:13:04 AM] - ERROR - status.py - MainThread - write - self.objects = self.load_objects()
[03/04/2014 01:13:04 AM] - ERROR - status.py - MainThread - write -   File "/usr/lib/python3.3/site-packages/i3situation-1.0.3-py3.3.egg/i3situation/core/plugin_manager.py", line 167, in load_objects

[03/04/2014 01:13:04 AM] - ERROR - status.py - MainThread - write -     
[03/04/2014 01:13:04 AM] - ERROR - status.py - MainThread - write - if settings['plugin'] in self.plugins:
[03/04/2014 01:13:04 AM] - ERROR - status.py - MainThread - write - KeyError
[03/04/2014 01:13:04 AM] - ERROR - status.py - MainThread - write - : 
[03/04/2014 01:13:04 AM] - ERROR - status.py - MainThread - write - 'plugin'
[03/04/2014 01:13:39 AM] - ERROR - status.py - MainThread - write - Traceback (most recent call last):

[03/04/2014 01:13:39 AM] - ERROR - status.py - MainThread - write -   File "/usr/bin/i3situation", line 9, in <module>

[03/04/2014 01:13:39 AM] - ERROR - status.py - MainThread - write -     
[03/04/2014 01:13:39 AM] - ERROR - status.py - MainThread - write - load_entry_point('i3situation==1.0.3', 'console_scripts', 'i3situation')()
[03/04/2014 01:13:39 AM] - ERROR - status.py - MainThread - write -   File "/usr/lib/python3.3/site-packages/i3situation-1.0.3-py3.3.egg/i3situation/main.py", line 7, in main

[03/04/2014 01:13:39 AM] - ERROR - status.py - MainThread - write -     
[03/04/2014 01:13:39 AM] - ERROR - status.py - MainThread - write - s = status.Status()
[03/04/2014 01:13:39 AM] - ERROR - status.py - MainThread - write -   File "/usr/lib/python3.3/site-packages/i3situation-1.0.3-py3.3.egg/i3situation/core/status.py", line 60, in __init__

[03/04/2014 01:13:39 AM] - ERROR - status.py - MainThread - write -     
[03/04/2014 01:13:39 AM] - ERROR - status.py - MainThread - write - self._plugin_path, self.config.plugin)
[03/04/2014 01:13:39 AM] - ERROR - status.py - MainThread - write -   File "/usr/lib/python3.3/site-packages/i3situation-1.0.3-py3.3.egg/i3situation/core/plugin_manager.py", line 123, in __init__

[03/04/2014 01:13:39 AM] - ERROR - status.py - MainThread - write -     
[03/04/2014 01:13:39 AM] - ERROR - status.py - MainThread - write - self.objects = self.load_objects()
[03/04/2014 01:13:39 AM] - ERROR - status.py - MainThread - write -   File "/usr/lib/python3.3/site-packages/i3situation-1.0.3-py3.3.egg/i3situation/core/plugin_manager.py", line 167, in load_objects

[03/04/2014 01:13:39 AM] - ERROR - status.py - MainThread - write -     
[03/04/2014 01:13:39 AM] - ERROR - status.py - MainThread - write - if settings['plugin'] in self.plugins:
[03/04/2014 01:13:39 AM] - ERROR - status.py - MainThread - write - KeyError
[03/04/2014 01:13:39 AM] - ERROR - status.py - MainThread - write - : 
[03/04/2014 01:13:39 AM] - ERROR - status.py - MainThread - write - 'plugin'
[03/04/2014 01:13:49 AM] - ERROR - status.py - MainThread - write - Traceback (most recent call last):

[03/04/2014 01:13:49 AM] - ERROR - status.py - MainThread - write -   File "/usr/bin/i3situation", line 9, in <module>

[03/04/2014 01:13:49 AM] - ERROR - status.py - MainThread - write -     
[03/04/2014 01:13:49 AM] - ERROR - status.py - MainThread - write - load_entry_point('i3situation==1.0.3', 'console_scripts', 'i3situation')()
[03/04/2014 01:13:49 AM] - ERROR - status.py - MainThread - write -   File "/usr/lib/python3.3/site-packages/i3situation-1.0.3-py3.3.egg/i3situation/main.py", line 7, in main

[03/04/2014 01:13:49 AM] - ERROR - status.py - MainThread - write -     
[03/04/2014 01:13:49 AM] - ERROR - status.py - MainThread - write - s = status.Status()
[03/04/2014 01:13:49 AM] - ERROR - status.py - MainThread - write -   File "/usr/lib/python3.3/site-packages/i3situation-1.0.3-py3.3.egg/i3situation/core/status.py", line 60, in __init__

[03/04/2014 01:13:49 AM] - ERROR - status.py - MainThread - write -     
[03/04/2014 01:13:49 AM] - ERROR - status.py - MainThread - write - self._plugin_path, self.config.plugin)
[03/04/2014 01:13:49 AM] - ERROR - status.py - MainThread - write -   File "/usr/lib/python3.3/site-packages/i3situation-1.0.3-py3.3.egg/i3situation/core/plugin_manager.py", line 123, in __init__

[03/04/2014 01:13:49 AM] - ERROR - status.py - MainThread - write -     
[03/04/2014 01:13:49 AM] - ERROR - status.py - MainThread - write - self.objects = self.load_objects()
[03/04/2014 01:13:49 AM] - ERROR - status.py - MainThread - write -   File "/usr/lib/python3.3/site-packages/i3situation-1.0.3-py3.3.egg/i3situation/core/plugin_manager.py", line 167, in load_objects

[03/04/2014 01:13:49 AM] - ERROR - status.py - MainThread - write -     
[03/04/2014 01:13:49 AM] - ERROR - status.py - MainThread - write - if settings['plugin'] in self.plugins:
[03/04/2014 01:13:49 AM] - ERROR - status.py - MainThread - write - KeyError
[03/04/2014 01:13:49 AM] - ERROR - status.py - MainThread - write - : 
[03/04/2014 01:13:49 AM] - ERROR - status.py - MainThread - write - 'plugin'
[03/04/2014 01:15:00 AM] - ERROR - status.py - MainThread - write - Traceback (most recent call last):

[03/04/2014 01:15:00 AM] - ERROR - status.py - MainThread - write -   File "/usr/bin/i3situation", line 9, in <module>

[03/04/2014 01:15:00 AM] - ERROR - status.py - MainThread - write -     
[03/04/2014 01:15:00 AM] - ERROR - status.py - MainThread - write - load_entry_point('i3situation==1.0.3', 'console_scripts', 'i3situation')()
[03/04/2014 01:15:00 AM] - ERROR - status.py - MainThread - write -   File "/usr/lib/python3.3/site-packages/i3situation-1.0.3-py3.3.egg/i3situation/main.py", line 7, in main

[03/04/2014 01:15:00 AM] - ERROR - status.py - MainThread - write -     
[03/04/2014 01:15:00 AM] - ERROR - status.py - MainThread - write - s = status.Status()
[03/04/2014 01:15:00 AM] - ERROR - status.py - MainThread - write -   File "/usr/lib/python3.3/site-packages/i3situation-1.0.3-py3.3.egg/i3situation/core/status.py", line 60, in __init__

[03/04/2014 01:15:00 AM] - ERROR - status.py - MainThread - write -     
[03/04/2014 01:15:00 AM] - ERROR - status.py - MainThread - write - self._plugin_path, self.config.plugin)
[03/04/2014 01:15:00 AM] - ERROR - status.py - MainThread - write -   File "/usr/lib/python3.3/site-packages/i3situation-1.0.3-py3.3.egg/i3situation/core/plugin_manager.py", line 123, in __init__

[03/04/2014 01:15:00 AM] - ERROR - status.py - MainThread - write -     
[03/04/2014 01:15:00 AM] - ERROR - status.py - MainThread - write - self.objects = self.load_objects()
[03/04/2014 01:15:00 AM] - ERROR - status.py - MainThread - write -   File "/usr/lib/python3.3/site-packages/i3situation-1.0.3-py3.3.egg/i3situation/core/plugin_manager.py", line 167, in load_objects

[03/04/2014 01:15:00 AM] - ERROR - status.py - MainThread - write -     
[03/04/2014 01:15:00 AM] - ERROR - status.py - MainThread - write - if settings['plugin'] in self.plugins:
[03/04/2014 01:15:00 AM] - ERROR - status.py - MainThread - write - KeyError
[03/04/2014 01:15:00 AM] - ERROR - status.py - MainThread - write - : 
[03/04/2014 01:15:00 AM] - ERROR - status.py - MainThread - write - 'plugin'
[03/04/2014 01:17:05 AM] - ERROR - status.py - MainThread - write - Traceback (most recent call last):

[03/04/2014 01:17:05 AM] - ERROR - status.py - MainThread - write -   File "/usr/bin/i3situation", line 9, in <module>

[03/04/2014 01:17:05 AM] - ERROR - status.py - MainThread - write -     
[03/04/2014 01:17:05 AM] - ERROR - status.py - MainThread - write - load_entry_point('i3situation==1.0.3', 'console_scripts', 'i3situation')()
[03/04/2014 01:17:05 AM] - ERROR - status.py - MainThread - write -   File "/usr/lib/python3.3/site-packages/i3situation-1.0.3-py3.3.egg/i3situation/main.py", line 7, in main

[03/04/2014 01:17:05 AM] - ERROR - status.py - MainThread - write -     
[03/04/2014 01:17:05 AM] - ERROR - status.py - MainThread - write - s = status.Status()
[03/04/2014 01:17:05 AM] - ERROR - status.py - MainThread - write -   File "/usr/lib/python3.3/site-packages/i3situation-1.0.3-py3.3.egg/i3situation/core/status.py", line 60, in __init__

[03/04/2014 01:17:05 AM] - ERROR - status.py - MainThread - write -     
[03/04/2014 01:17:05 AM] - ERROR - status.py - MainThread - write - self._plugin_path, self.config.plugin)
[03/04/2014 01:17:05 AM] - ERROR - status.py - MainThread - write -   File "/usr/lib/python3.3/site-packages/i3situation-1.0.3-py3.3.egg/i3situation/core/plugin_manager.py", line 123, in __init__

[03/04/2014 01:17:05 AM] - ERROR - status.py - MainThread - write -     
[03/04/2014 01:17:05 AM] - ERROR - status.py - MainThread - write - self.objects = self.load_objects()
[03/04/2014 01:17:05 AM] - ERROR - status.py - MainThread - write -   File "/usr/lib/python3.3/site-packages/i3situation-1.0.3-py3.3.egg/i3situation/core/plugin_manager.py", line 167, in load_objects

[03/04/2014 01:17:05 AM] - ERROR - status.py - MainThread - write -     
[03/04/2014 01:17:05 AM] - ERROR - status.py - MainThread - write - if settings['plugin'] in self.plugins:
[03/04/2014 01:17:05 AM] - ERROR - status.py - MainThread - write - KeyError
[03/04/2014 01:17:05 AM] - ERROR - status.py - MainThread - write - : 
[03/04/2014 01:17:05 AM] - ERROR - status.py - MainThread - write - 'plugin'
[03/04/2014 01:17:10 AM] - ERROR - status.py - MainThread - write - Traceback (most recent call last):

[03/04/2014 01:17:10 AM] - ERROR - status.py - MainThread - write -   File "/usr/bin/i3situation", line 9, in <module>

[03/04/2014 01:17:10 AM] - ERROR - status.py - MainThread - write -     
[03/04/2014 01:17:10 AM] - ERROR - status.py - MainThread - write - load_entry_point('i3situation==1.0.3', 'console_scripts', 'i3situation')()
[03/04/2014 01:17:10 AM] - ERROR - status.py - MainThread - write -   File "/usr/lib/python3.3/site-packages/i3situation-1.0.3-py3.3.egg/i3situation/main.py", line 7, in main

[03/04/2014 01:17:10 AM] - ERROR - status.py - MainThread - write -     
[03/04/2014 01:17:10 AM] - ERROR - status.py - MainThread - write - s = status.Status()
[03/04/2014 01:17:10 AM] - ERROR - status.py - MainThread - write -   File "/usr/lib/python3.3/site-packages/i3situation-1.0.3-py3.3.egg/i3situation/core/status.py", line 60, in __init__

[03/04/2014 01:17:10 AM] - ERROR - status.py - MainThread - write -     
[03/04/2014 01:17:10 AM] - ERROR - status.py - MainThread - write - self._plugin_path, self.config.plugin)
[03/04/2014 01:17:10 AM] - ERROR - status.py - MainThread - write -   File "/usr/lib/python3.3/site-packages/i3situation-1.0.3-py3.3.egg/i3situation/core/plugin_manager.py", line 123, in __init__

[03/04/2014 01:17:10 AM] - ERROR - status.py - MainThread - write -     
[03/04/2014 01:17:10 AM] - ERROR - status.py - MainThread - write - self.objects = self.load_objects()
[03/04/2014 01:17:10 AM] - ERROR - status.py - MainThread - write -   File "/usr/lib/python3.3/site-packages/i3situation-1.0.3-py3.3.egg/i3situation/core/plugin_manager.py", line 167, in load_objects

[03/04/2014 01:17:10 AM] - ERROR - status.py - MainThread - write -     
[03/04/2014 01:17:10 AM] - ERROR - status.py - MainThread - write - if settings['plugin'] in self.plugins:
[03/04/2014 01:17:10 AM] - ERROR - status.py - MainThread - write - KeyError
[03/04/2014 01:17:10 AM] - ERROR - status.py - MainThread - write - : 
[03/04/2014 01:17:10 AM] - ERROR - status.py - MainThread - write - 'plugin'
[03/04/2014 01:17:11 AM] - ERROR - status.py - MainThread - write - Traceback (most recent call last):

[03/04/2014 01:17:11 AM] - ERROR - status.py - MainThread - write -   File "/usr/bin/i3situation", line 9, in <module>

[03/04/2014 01:17:11 AM] - ERROR - status.py - MainThread - write -     
[03/04/2014 01:17:11 AM] - ERROR - status.py - MainThread - write - load_entry_point('i3situation==1.0.3', 'console_scripts', 'i3situation')()
[03/04/2014 01:17:11 AM] - ERROR - status.py - MainThread - write -   File "/usr/lib/python3.3/site-packages/i3situation-1.0.3-py3.3.egg/i3situation/main.py", line 7, in main

[03/04/2014 01:17:11 AM] - ERROR - status.py - MainThread - write -     
[03/04/2014 01:17:11 AM] - ERROR - status.py - MainThread - write - s = status.Status()
[03/04/2014 01:17:11 AM] - ERROR - status.py - MainThread - write -   File "/usr/lib/python3.3/site-packages/i3situation-1.0.3-py3.3.egg/i3situation/core/status.py", line 60, in __init__

[03/04/2014 01:17:11 AM] - ERROR - status.py - MainThread - write -     
[03/04/2014 01:17:11 AM] - ERROR - status.py - MainThread - write - self._plugin_path, self.config.plugin)
[03/04/2014 01:17:11 AM] - ERROR - status.py - MainThread - write -   File "/usr/lib/python3.3/site-packages/i3situation-1.0.3-py3.3.egg/i3situation/core/plugin_manager.py", line 123, in __init__

[03/04/2014 01:17:11 AM] - ERROR - status.py - MainThread - write -     
[03/04/2014 01:17:11 AM] - ERROR - status.py - MainThread - write - self.objects = self.load_objects()
[03/04/2014 01:17:11 AM] - ERROR - status.py - MainThread - write -   File "/usr/lib/python3.3/site-packages/i3situation-1.0.3-py3.3.egg/i3situation/core/plugin_manager.py", line 167, in load_objects

[03/04/2014 01:17:11 AM] - ERROR - status.py - MainThread - write -     
[03/04/2014 01:17:11 AM] - ERROR - status.py - MainThread - write - if settings['plugin'] in self.plugins:
[03/04/2014 01:17:11 AM] - ERROR - status.py - MainThread - write - KeyError
[03/04/2014 01:17:11 AM] - ERROR - status.py - MainThread - write - : 
[03/04/2014 01:17:11 AM] - ERROR - status.py - MainThread - write - 'plugin'
[03/04/2014 01:18:33 AM] - ERROR - status.py - MainThread - write - Traceback (most recent call last):

[03/04/2014 01:18:33 AM] - ERROR - status.py - MainThread - write -   File "/usr/bin/i3situation", line 9, in <module>

[03/04/2014 01:18:33 AM] - ERROR - status.py - MainThread - write -     
[03/04/2014 01:18:33 AM] - ERROR - status.py - MainThread - write - load_entry_point('i3situation==1.0.3', 'console_scripts', 'i3situation')()
[03/04/2014 01:18:33 AM] - ERROR - status.py - MainThread - write -   File "/usr/lib/python3.3/site-packages/i3situation-1.0.3-py3.3.egg/i3situation/main.py", line 7, in main

[03/04/2014 01:18:33 AM] - ERROR - status.py - MainThread - write -     
[03/04/2014 01:18:33 AM] - ERROR - status.py - MainThread - write - s = status.Status()
[03/04/2014 01:18:33 AM] - ERROR - status.py - MainThread - write -   File "/usr/lib/python3.3/site-packages/i3situation-1.0.3-py3.3.egg/i3situation/core/status.py", line 60, in __init__

[03/04/2014 01:18:33 AM] - ERROR - status.py - MainThread - write -     
[03/04/2014 01:18:33 AM] - ERROR - status.py - MainThread - write - self._plugin_path, self.config.plugin)
[03/04/2014 01:18:33 AM] - ERROR - status.py - MainThread - write -   File "/usr/lib/python3.3/site-packages/i3situation-1.0.3-py3.3.egg/i3situation/core/plugin_manager.py", line 123, in __init__

[03/04/2014 01:18:33 AM] - ERROR - status.py - MainThread - write -     
[03/04/2014 01:18:33 AM] - ERROR - status.py - MainThread - write - self.objects = self.load_objects()
[03/04/2014 01:18:33 AM] - ERROR - status.py - MainThread - write -   File "/usr/lib/python3.3/site-packages/i3situation-1.0.3-py3.3.egg/i3situation/core/plugin_manager.py", line 167, in load_objects

[03/04/2014 01:18:33 AM] - ERROR - status.py - MainThread - write -     
[03/04/2014 01:18:33 AM] - ERROR - status.py - MainThread - write - if settings['plugin'] in self.plugins:
[03/04/2014 01:18:33 AM] - ERROR - status.py - MainThread - write - KeyError
[03/04/2014 01:18:33 AM] - ERROR - status.py - MainThread - write - : 
[03/04/2014 01:18:33 AM] - ERROR - status.py - MainThread - write - 'plugin'
[03/04/2014 01:19:08 AM] - ERROR - status.py - MainThread - write - Traceback (most recent call last):

[03/04/2014 01:19:08 AM] - ERROR - status.py - MainThread - write -   File "/usr/bin/i3situation", line 9, in <module>

[03/04/2014 01:19:08 AM] - ERROR - status.py - MainThread - write -     
[03/04/2014 01:19:08 AM] - ERROR - status.py - MainThread - write - load_entry_point('i3situation==1.0.3', 'console_scripts', 'i3situation')()
[03/04/2014 01:19:08 AM] - ERROR - status.py - MainThread - write -   File "/usr/lib/python3.3/site-packages/i3situation-1.0.3-py3.3.egg/i3situation/main.py", line 7, in main

[03/04/2014 01:19:08 AM] - ERROR - status.py - MainThread - write -     
[03/04/2014 01:19:08 AM] - ERROR - status.py - MainThread - write - s = status.Status()
[03/04/2014 01:19:08 AM] - ERROR - status.py - MainThread - write -   File "/usr/lib/python3.3/site-packages/i3situation-1.0.3-py3.3.egg/i3situation/core/status.py", line 60, in __init__

[03/04/2014 01:19:08 AM] - ERROR - status.py - MainThread - write -     
[03/04/2014 01:19:08 AM] - ERROR - status.py - MainThread - write - self._plugin_path, self.config.plugin)
[03/04/2014 01:19:08 AM] - ERROR - status.py - MainThread - write -   File "/usr/lib/python3.3/site-packages/i3situation-1.0.3-py3.3.egg/i3situation/core/plugin_manager.py", line 123, in __init__

[03/04/2014 01:19:08 AM] - ERROR - status.py - MainThread - write -     
[03/04/2014 01:19:08 AM] - ERROR - status.py - MainThread - write - self.objects = self.load_objects()
[03/04/2014 01:19:08 AM] - ERROR - status.py - MainThread - write -   File "/usr/lib/python3.3/site-packages/i3situation-1.0.3-py3.3.egg/i3situation/core/plugin_manager.py", line 167, in load_objects

[03/04/2014 01:19:08 AM] - ERROR - status.py - MainThread - write -     
[03/04/2014 01:19:08 AM] - ERROR - status.py - MainThread - write - if settings['plugin'] in self.plugins:
[03/04/2014 01:19:08 AM] - ERROR - status.py - MainThread - write - KeyError
[03/04/2014 01:19:08 AM] - ERROR - status.py - MainThread - write - : 
[03/04/2014 01:19:08 AM] - ERROR - status.py - MainThread - write - 'plugin'
[03/04/2014 01:20:27 AM] - ERROR - status.py - MainThread - write - Traceback (most recent call last):

[03/04/2014 01:20:27 AM] - ERROR - status.py - MainThread - write -   File "/usr/bin/i3situation", line 9, in <module>

[03/04/2014 01:20:27 AM] - ERROR - status.py - MainThread - write -     
[03/04/2014 01:20:27 AM] - ERROR - status.py - MainThread - write - load_entry_point('i3situation==1.0.3', 'console_scripts', 'i3situation')()
[03/04/2014 01:20:27 AM] - ERROR - status.py - MainThread - write -   File "/usr/lib/python3.3/site-packages/i3situation-1.0.3-py3.3.egg/i3situation/main.py", line 7, in main

[03/04/2014 01:20:27 AM] - ERROR - status.py - MainThread - write -     
[03/04/2014 01:20:27 AM] - ERROR - status.py - MainThread - write - s = status.Status()
[03/04/2014 01:20:27 AM] - ERROR - status.py - MainThread - write -   File "/usr/lib/python3.3/site-packages/i3situation-1.0.3-py3.3.egg/i3situation/core/status.py", line 60, in __init__

[03/04/2014 01:20:27 AM] - ERROR - status.py - MainThread - write -     
[03/04/2014 01:20:27 AM] - ERROR - status.py - MainThread - write - self._plugin_path, self.config.plugin)
[03/04/2014 01:20:27 AM] - ERROR - status.py - MainThread - write -   File "/usr/lib/python3.3/site-packages/i3situation-1.0.3-py3.3.egg/i3situation/core/plugin_manager.py", line 123, in __init__

[03/04/2014 01:20:27 AM] - ERROR - status.py - MainThread - write -     
[03/04/2014 01:20:27 AM] - ERROR - status.py - MainThread - write - self.objects = self.load_objects()
[03/04/2014 01:20:27 AM] - ERROR - status.py - MainThread - write -   File "/usr/lib/python3.3/site-packages/i3situation-1.0.3-py3.3.egg/i3situation/core/plugin_manager.py", line 171, in load_objects

[03/04/2014 01:20:27 AM] - ERROR - status.py - MainThread - write -     
[03/04/2014 01:20:27 AM] - ERROR - status.py - MainThread - write - plugin_class = getattr(module, module.__all__)
[03/04/2014 01:20:27 AM] - ERROR - status.py - MainThread - write - AttributeError
[03/04/2014 01:20:27 AM] - ERROR - status.py - MainThread - write - : 
[03/04/2014 01:20:27 AM] - ERROR - status.py - MainThread - write - 'module' object has no attribute 'BatteryPlugin'
[03/04/2014 01:20:31 AM] - ERROR - status.py - MainThread - write - Traceback (most recent call last):

[03/04/2014 01:20:31 AM] - ERROR - status.py - MainThread - write -   File "/usr/bin/i3situation", line 9, in <module>

[03/04/2014 01:20:31 AM] - ERROR - status.py - MainThread - write -     
[03/04/2014 01:20:31 AM] - ERROR - status.py - MainThread - write - load_entry_point('i3situation==1.0.3', 'console_scripts', 'i3situation')()
[03/04/2014 01:20:31 AM] - ERROR - status.py - MainThread - write -   File "/usr/lib/python3.3/site-packages/i3situation-1.0.3-py3.3.egg/i3situation/main.py", line 7, in main

[03/04/2014 01:20:31 AM] - ERROR - status.py - MainThread - write -     
[03/04/2014 01:20:31 AM] - ERROR - status.py - MainThread - write - s = status.Status()
[03/04/2014 01:20:31 AM] - ERROR - status.py - MainThread - write -   File "/usr/lib/python3.3/site-packages/i3situation-1.0.3-py3.3.egg/i3situation/core/status.py", line 60, in __init__

[03/04/2014 01:20:31 AM] - ERROR - status.py - MainThread - write -     
[03/04/2014 01:20:31 AM] - ERROR - status.py - MainThread - write - self._plugin_path, self.config.plugin)
[03/04/2014 01:20:31 AM] - ERROR - status.py - MainThread - write -   File "/usr/lib/python3.3/site-packages/i3situation-1.0.3-py3.3.egg/i3situation/core/plugin_manager.py", line 123, in __init__

[03/04/2014 01:20:31 AM] - ERROR - status.py - MainThread - write -     
[03/04/2014 01:20:31 AM] - ERROR - status.py - MainThread - write - self.objects = self.load_objects()
[03/04/2014 01:20:31 AM] - ERROR - status.py - MainThread - write -   File "/usr/lib/python3.3/site-packages/i3situation-1.0.3-py3.3.egg/i3situation/core/plugin_manager.py", line 171, in load_objects

[03/04/2014 01:20:31 AM] - ERROR - status.py - MainThread - write -     
[03/04/2014 01:20:31 AM] - ERROR - status.py - MainThread - write - plugin_class = getattr(module, module.__all__)
[03/04/2014 01:20:31 AM] - ERROR - status.py - MainThread - write - AttributeError
[03/04/2014 01:20:31 AM] - ERROR - status.py - MainThread - write - : 
[03/04/2014 01:20:31 AM] - ERROR - status.py - MainThread - write - 'module' object has no attribute 'BatteryPlugin'
[03/04/2014 01:21:03 AM] - ERROR - status.py - Thread-4 - write - Exception in thread Thread-4:
Traceback (most recent call last):
  File "/usr/lib/python3.3/threading.py", line 901, in _bootstrap_inner
    self.run()
  File "/usr/lib/python3.3/site-packages/i3situation-1.0.3-py3.3.egg/i3situation/core/plugin_manager.py", line 52, in run
    ret = self.func()
  File "/home/andrew/.config/i3situation/plugins/network.py", line 16, in main
    iface = netifaces.ifaddresses(ifaceName).get(netifaces.AF_INET)
ValueError: You must specify a valid interface name.


[03/04/2014 12:21:04 AM] - ERROR - status.py - MainThread - write - Traceback (most recent call last):

[03/04/2014 12:21:04 AM] - ERROR - status.py - MainThread - write -   File "/usr/bin/i3situation", line 9, in <module>

[03/04/2014 12:21:04 AM] - ERROR - status.py - MainThread - write -     
[03/04/2014 12:21:04 AM] - ERROR - status.py - MainThread - write - load_entry_point('i3situation==1.0.3', 'console_scripts', 'i3situation')()
[03/04/2014 12:21:04 AM] - ERROR - status.py - MainThread - write -   File "/usr/lib/python3.3/site-packages/i3situation-1.0.3-py3.3.egg/i3situation/main.py", line 9, in main

[03/04/2014 12:21:04 AM] - ERROR - status.py - MainThread - write -     
[03/04/2014 12:21:04 AM] - ERROR - status.py - MainThread - write - s.run()
[03/04/2014 12:21:04 AM] - ERROR - status.py - MainThread - write -   File "/usr/lib/python3.3/site-packages/i3situation-1.0.3-py3.3.egg/i3situation/core/status.py", line 127, in run

[03/04/2014 12:21:04 AM] - ERROR - status.py - MainThread - write -     
[03/04/2014 12:21:04 AM] - ERROR - status.py - MainThread - write - time.sleep(self.config.general['interval'])
[03/04/2014 12:21:04 AM] - ERROR - status.py - MainThread - write - KeyboardInterrupt
[03/04/2014 12:21:04 AM] - ERROR - status.py - MainThread - write - 
[03/04/2014 12:21:05 AM] - ERROR - status.py - MainThread - write - Exception 
[03/04/2014 12:21:05 AM] - ERROR - status.py - MainThread - write - KeyboardInterrupt
[03/04/2014 12:21:05 AM] - ERROR - status.py - MainThread - write - : 
[03/04/2014 12:21:05 AM] - ERROR - status.py - MainThread - write - KeyboardInterrupt()
[03/04/2014 12:21:05 AM] - ERROR - status.py - MainThread - write -  in 
[03/04/2014 12:21:05 AM] - ERROR - status.py - MainThread - write - <module 'threading' from '/usr/lib/python3.3/threading.py'>
[03/04/2014 12:21:05 AM] - ERROR - status.py - MainThread - write -  ignored

[03/04/2014 01:21:06 AM] - ERROR - status.py - Thread-4 - write - Exception in thread Thread-4:
Traceback (most recent call last):
  File "/usr/lib/python3.3/threading.py", line 901, in _bootstrap_inner
    self.run()
  File "/usr/lib/python3.3/site-packages/i3situation-1.0.3-py3.3.egg/i3situation/core/plugin_manager.py", line 52, in run
    ret = self.func()
  File "/home/andrew/.config/i3situation/plugins/network.py", line 16, in main
    iface = netifaces.ifaddresses(ifaceName).get(netifaces.AF_INET)
ValueError: You must specify a valid interface name.


